[I 2025-10-18 11:44:53.058 ServerApp] jupyter_lsp | extension was successfully linked.
[I 2025-10-18 11:44:53.061 ServerApp] jupyter_server_terminals | extension was successfully linked.
[I 2025-10-18 11:44:53.064 ServerApp] jupyterlab | extension was successfully linked.
[W 2025-10-18 11:44:53.065 JupyterNotebookApp] 'ip' has moved from NotebookApp to ServerApp. This config will be passed to ServerApp. Be sure to update your config before our next release.
[W 2025-10-18 11:44:53.066 JupyterNotebookApp] 'port' has moved from NotebookApp to ServerApp. This config will be passed to ServerApp. Be sure to update your config before our next release.
[W 2025-10-18 11:44:53.066 JupyterNotebookApp] 'port' has moved from NotebookApp to ServerApp. This config will be passed to ServerApp. Be sure to update your config before our next release.
[I 2025-10-18 11:44:53.068 ServerApp] notebook | extension was successfully linked.
[I 2025-10-18 11:44:53.236 ServerApp] notebook_shim | extension was successfully linked.
[I 2025-10-18 11:44:53.251 ServerApp] notebook_shim | extension was successfully loaded.
[I 2025-10-18 11:44:53.253 ServerApp] jupyter_lsp | extension was successfully loaded.
[I 2025-10-18 11:44:53.254 ServerApp] jupyter_server_terminals | extension was successfully loaded.
[I 2025-10-18 11:44:53.256 LabApp] JupyterLab extension loaded from /usr/local/lib/python3.9/site-packages/jupyterlab
[I 2025-10-18 11:44:53.256 LabApp] JupyterLab application directory is /usr/local/share/jupyter/lab
[I 2025-10-18 11:44:53.256 LabApp] Extension Manager is 'pypi'.
[I 2025-10-18 11:44:53.280 ServerApp] jupyterlab | extension was successfully loaded.
[I 2025-10-18 11:44:53.282 ServerApp] notebook | extension was successfully loaded.
[I 2025-10-18 11:44:53.283 ServerApp] Serving notebooks from local directory: /home/ricardo/fine-tuning-llm
[I 2025-10-18 11:44:53.283 ServerApp] Jupyter Server 2.17.0 is running at:
[I 2025-10-18 11:44:53.283 ServerApp] http://srv-pjc-ia:8888/tree
[I 2025-10-18 11:44:53.283 ServerApp]     http://127.0.0.1:8888/tree
[I 2025-10-18 11:44:53.283 ServerApp] Use Control-C to stop this server and shut down all kernels (twice to skip confirmation).
[I 2025-10-18 11:44:53.300 ServerApp] Skipped non-installed server(s): basedpyright, bash-language-server, dockerfile-language-server-nodejs, javascript-typescript-langserver, jedi-language-server, julia-language-server, pyrefly, pyright, python-language-server, python-lsp-server, r-languageserver, sql-language-server, texlab, typescript-language-server, unified-language-server, vscode-css-languageserver-bin, vscode-html-languageserver-bin, vscode-json-languageserver-bin, yaml-language-server
[W 2025-10-18 11:44:55.923 ServerApp] 404 GET /api/kernels/ce2c092f-f394-4b03-98ba-df9da361be68?1760798695905 (192.168.241.22): Kernel does not exist: ce2c092f-f394-4b03-98ba-df9da361be68
[W 2025-10-18 11:44:55.924 ServerApp] wrote error: 'Kernel does not exist: ce2c092f-f394-4b03-98ba-df9da361be68'
    Traceback (most recent call last):
      File "/usr/local/lib64/python3.9/site-packages/tornado/web.py", line 1848, in _execute
        result = await result
      File "/usr/local/lib/python3.9/site-packages/jupyter_server/auth/decorator.py", line 73, in inner
        return await out
      File "/usr/local/lib/python3.9/site-packages/jupyter_server/services/kernels/handlers.py", line 75, in get
        model = await ensure_async(km.kernel_model(kernel_id))
      File "/usr/local/lib/python3.9/site-packages/jupyter_server/services/kernels/kernelmanager.py", line 513, in kernel_model
        self._check_kernel_id(kernel_id)
      File "/usr/local/lib/python3.9/site-packages/jupyter_server/services/kernels/kernelmanager.py", line 544, in _check_kernel_id
        raise web.HTTPError(404, "Kernel does not exist: %s" % kernel_id)
    tornado.web.HTTPError: HTTP 404: Not Found (Kernel does not exist: ce2c092f-f394-4b03-98ba-df9da361be68)
[W 2025-10-18 11:44:55.926 ServerApp] 404 GET /api/kernels/ce2c092f-f394-4b03-98ba-df9da361be68?1760798695905 (d83dba3d5f47438d8a33fc3bbb8e9bfa@192.168.241.22) 3.44ms referer=https://jupyter.pjc.mt.gov.br/notebooks/PEFT-LoRA/peft-lora.ipynb
[W 2025-10-18 11:44:56.921 ServerApp] 404 GET /api/kernels/ce2c092f-f394-4b03-98ba-df9da361be68/channels?session_id=82a95311-40a8-4a13-8c35-46c720401253 (192.168.241.22): Kernel does not exist: ce2c092f-f394-4b03-98ba-df9da361be68
[W 2025-10-18 11:44:56.934 ServerApp] 404 GET /api/kernels/ce2c092f-f394-4b03-98ba-df9da361be68/channels?session_id=82a95311-40a8-4a13-8c35-46c720401253 (d83dba3d5f47438d8a33fc3bbb8e9bfa@192.168.241.22) 13.21ms referer=None
[W 2025-10-18 11:44:56.942 ServerApp] 404 GET /api/kernels/ce2c092f-f394-4b03-98ba-df9da361be68?1760798696931 (192.168.241.22): Kernel does not exist: ce2c092f-f394-4b03-98ba-df9da361be68
[W 2025-10-18 11:44:56.942 ServerApp] wrote error: 'Kernel does not exist: ce2c092f-f394-4b03-98ba-df9da361be68'
    Traceback (most recent call last):
      File "/usr/local/lib64/python3.9/site-packages/tornado/web.py", line 1848, in _execute
        result = await result
      File "/usr/local/lib/python3.9/site-packages/jupyter_server/auth/decorator.py", line 73, in inner
        return await out
      File "/usr/local/lib/python3.9/site-packages/jupyter_server/services/kernels/handlers.py", line 75, in get
        model = await ensure_async(km.kernel_model(kernel_id))
      File "/usr/local/lib/python3.9/site-packages/jupyter_server/services/kernels/kernelmanager.py", line 513, in kernel_model
        self._check_kernel_id(kernel_id)
      File "/usr/local/lib/python3.9/site-packages/jupyter_server/services/kernels/kernelmanager.py", line 544, in _check_kernel_id
        raise web.HTTPError(404, "Kernel does not exist: %s" % kernel_id)
    tornado.web.HTTPError: HTTP 404: Not Found (Kernel does not exist: ce2c092f-f394-4b03-98ba-df9da361be68)
[W 2025-10-18 11:44:56.942 ServerApp] 404 GET /api/kernels/ce2c092f-f394-4b03-98ba-df9da361be68?1760798696931 (d83dba3d5f47438d8a33fc3bbb8e9bfa@192.168.241.22) 1.12ms referer=https://jupyter.pjc.mt.gov.br/notebooks/PEFT-LoRA/peft-lora.ipynb
[W 2025-10-18 11:44:57.921 ServerApp] 404 GET /api/kernels/ce2c092f-f394-4b03-98ba-df9da361be68/channels?session_id=82a95311-40a8-4a13-8c35-46c720401253 (192.168.241.22): Kernel does not exist: ce2c092f-f394-4b03-98ba-df9da361be68
[W 2025-10-18 11:44:57.921 ServerApp] 404 GET /api/kernels/ce2c092f-f394-4b03-98ba-df9da361be68/channels?session_id=82a95311-40a8-4a13-8c35-46c720401253 (d83dba3d5f47438d8a33fc3bbb8e9bfa@192.168.241.22) 1.16ms referer=None
[W 2025-10-18 11:44:57.929 ServerApp] 404 GET /api/kernels/ce2c092f-f394-4b03-98ba-df9da361be68?1760798697918 (192.168.241.22): Kernel does not exist: ce2c092f-f394-4b03-98ba-df9da361be68
[W 2025-10-18 11:44:57.929 ServerApp] wrote error: 'Kernel does not exist: ce2c092f-f394-4b03-98ba-df9da361be68'
    Traceback (most recent call last):
      File "/usr/local/lib64/python3.9/site-packages/tornado/web.py", line 1848, in _execute
        result = await result
      File "/usr/local/lib/python3.9/site-packages/jupyter_server/auth/decorator.py", line 73, in inner
        return await out
      File "/usr/local/lib/python3.9/site-packages/jupyter_server/services/kernels/handlers.py", line 75, in get
        model = await ensure_async(km.kernel_model(kernel_id))
      File "/usr/local/lib/python3.9/site-packages/jupyter_server/services/kernels/kernelmanager.py", line 513, in kernel_model
        self._check_kernel_id(kernel_id)
      File "/usr/local/lib/python3.9/site-packages/jupyter_server/services/kernels/kernelmanager.py", line 544, in _check_kernel_id
        raise web.HTTPError(404, "Kernel does not exist: %s" % kernel_id)
    tornado.web.HTTPError: HTTP 404: Not Found (Kernel does not exist: ce2c092f-f394-4b03-98ba-df9da361be68)
[W 2025-10-18 11:44:57.929 ServerApp] 404 GET /api/kernels/ce2c092f-f394-4b03-98ba-df9da361be68?1760798697918 (d83dba3d5f47438d8a33fc3bbb8e9bfa@192.168.241.22) 0.91ms referer=https://jupyter.pjc.mt.gov.br/notebooks/PEFT-LoRA/peft-lora.ipynb
[W 2025-10-18 11:44:59.921 ServerApp] 404 GET /api/kernels/ce2c092f-f394-4b03-98ba-df9da361be68/channels?session_id=82a95311-40a8-4a13-8c35-46c720401253 (192.168.241.22): Kernel does not exist: ce2c092f-f394-4b03-98ba-df9da361be68
[W 2025-10-18 11:44:59.922 ServerApp] 404 GET /api/kernels/ce2c092f-f394-4b03-98ba-df9da361be68/channels?session_id=82a95311-40a8-4a13-8c35-46c720401253 (d83dba3d5f47438d8a33fc3bbb8e9bfa@192.168.241.22) 1.60ms referer=None
[W 2025-10-18 11:44:59.932 ServerApp] 404 GET /api/kernels/ce2c092f-f394-4b03-98ba-df9da361be68?1760798699919 (192.168.241.22): Kernel does not exist: ce2c092f-f394-4b03-98ba-df9da361be68
[W 2025-10-18 11:44:59.932 ServerApp] wrote error: 'Kernel does not exist: ce2c092f-f394-4b03-98ba-df9da361be68'
    Traceback (most recent call last):
      File "/usr/local/lib64/python3.9/site-packages/tornado/web.py", line 1848, in _execute
        result = await result
      File "/usr/local/lib/python3.9/site-packages/jupyter_server/auth/decorator.py", line 73, in inner
        return await out
      File "/usr/local/lib/python3.9/site-packages/jupyter_server/services/kernels/handlers.py", line 75, in get
        model = await ensure_async(km.kernel_model(kernel_id))
      File "/usr/local/lib/python3.9/site-packages/jupyter_server/services/kernels/kernelmanager.py", line 513, in kernel_model
        self._check_kernel_id(kernel_id)
      File "/usr/local/lib/python3.9/site-packages/jupyter_server/services/kernels/kernelmanager.py", line 544, in _check_kernel_id
        raise web.HTTPError(404, "Kernel does not exist: %s" % kernel_id)
    tornado.web.HTTPError: HTTP 404: Not Found (Kernel does not exist: ce2c092f-f394-4b03-98ba-df9da361be68)
[W 2025-10-18 11:44:59.932 ServerApp] 404 GET /api/kernels/ce2c092f-f394-4b03-98ba-df9da361be68?1760798699919 (d83dba3d5f47438d8a33fc3bbb8e9bfa@192.168.241.22) 1.20ms referer=https://jupyter.pjc.mt.gov.br/notebooks/PEFT-LoRA/peft-lora.ipynb
[W 2025-10-18 11:45:14.931 ServerApp] 404 GET /api/kernels/ce2c092f-f394-4b03-98ba-df9da361be68/channels?session_id=82a95311-40a8-4a13-8c35-46c720401253 (192.168.241.22): Kernel does not exist: ce2c092f-f394-4b03-98ba-df9da361be68
[W 2025-10-18 11:45:14.932 ServerApp] 404 GET /api/kernels/ce2c092f-f394-4b03-98ba-df9da361be68/channels?session_id=82a95311-40a8-4a13-8c35-46c720401253 (d83dba3d5f47438d8a33fc3bbb8e9bfa@192.168.241.22) 1.38ms referer=None
[W 2025-10-18 11:45:14.939 ServerApp] 404 GET /api/kernels/ce2c092f-f394-4b03-98ba-df9da361be68?1760798714928 (192.168.241.22): Kernel does not exist: ce2c092f-f394-4b03-98ba-df9da361be68
[W 2025-10-18 11:45:14.939 ServerApp] wrote error: 'Kernel does not exist: ce2c092f-f394-4b03-98ba-df9da361be68'
    Traceback (most recent call last):
      File "/usr/local/lib64/python3.9/site-packages/tornado/web.py", line 1848, in _execute
        result = await result
      File "/usr/local/lib/python3.9/site-packages/jupyter_server/auth/decorator.py", line 73, in inner
        return await out
      File "/usr/local/lib/python3.9/site-packages/jupyter_server/services/kernels/handlers.py", line 75, in get
        model = await ensure_async(km.kernel_model(kernel_id))
      File "/usr/local/lib/python3.9/site-packages/jupyter_server/services/kernels/kernelmanager.py", line 513, in kernel_model
        self._check_kernel_id(kernel_id)
      File "/usr/local/lib/python3.9/site-packages/jupyter_server/services/kernels/kernelmanager.py", line 544, in _check_kernel_id
        raise web.HTTPError(404, "Kernel does not exist: %s" % kernel_id)
    tornado.web.HTTPError: HTTP 404: Not Found (Kernel does not exist: ce2c092f-f394-4b03-98ba-df9da361be68)
[W 2025-10-18 11:45:14.940 ServerApp] 404 GET /api/kernels/ce2c092f-f394-4b03-98ba-df9da361be68?1760798714928 (d83dba3d5f47438d8a33fc3bbb8e9bfa@192.168.241.22) 1.11ms referer=https://jupyter.pjc.mt.gov.br/notebooks/PEFT-LoRA/peft-lora.ipynb
[W 2025-10-18 11:45:33.933 ServerApp] 404 GET /api/kernels/ce2c092f-f394-4b03-98ba-df9da361be68/channels?session_id=82a95311-40a8-4a13-8c35-46c720401253 (192.168.241.22): Kernel does not exist: ce2c092f-f394-4b03-98ba-df9da361be68
[W 2025-10-18 11:45:33.933 ServerApp] 404 GET /api/kernels/ce2c092f-f394-4b03-98ba-df9da361be68/channels?session_id=82a95311-40a8-4a13-8c35-46c720401253 (d83dba3d5f47438d8a33fc3bbb8e9bfa@192.168.241.22) 1.27ms referer=None
[W 2025-10-18 11:45:33.940 ServerApp] 404 GET /api/kernels/ce2c092f-f394-4b03-98ba-df9da361be68?1760798733930 (192.168.241.22): Kernel does not exist: ce2c092f-f394-4b03-98ba-df9da361be68
[W 2025-10-18 11:45:33.941 ServerApp] wrote error: 'Kernel does not exist: ce2c092f-f394-4b03-98ba-df9da361be68'
    Traceback (most recent call last):
      File "/usr/local/lib64/python3.9/site-packages/tornado/web.py", line 1848, in _execute
        result = await result
      File "/usr/local/lib/python3.9/site-packages/jupyter_server/auth/decorator.py", line 73, in inner
        return await out
      File "/usr/local/lib/python3.9/site-packages/jupyter_server/services/kernels/handlers.py", line 75, in get
        model = await ensure_async(km.kernel_model(kernel_id))
      File "/usr/local/lib/python3.9/site-packages/jupyter_server/services/kernels/kernelmanager.py", line 513, in kernel_model
        self._check_kernel_id(kernel_id)
      File "/usr/local/lib/python3.9/site-packages/jupyter_server/services/kernels/kernelmanager.py", line 544, in _check_kernel_id
        raise web.HTTPError(404, "Kernel does not exist: %s" % kernel_id)
    tornado.web.HTTPError: HTTP 404: Not Found (Kernel does not exist: ce2c092f-f394-4b03-98ba-df9da361be68)
[W 2025-10-18 11:45:33.941 ServerApp] 404 GET /api/kernels/ce2c092f-f394-4b03-98ba-df9da361be68?1760798733930 (d83dba3d5f47438d8a33fc3bbb8e9bfa@192.168.241.22) 0.96ms referer=https://jupyter.pjc.mt.gov.br/notebooks/PEFT-LoRA/peft-lora.ipynb
[W 2025-10-18 11:46:28.934 ServerApp] 404 GET /api/kernels/ce2c092f-f394-4b03-98ba-df9da361be68/channels?session_id=82a95311-40a8-4a13-8c35-46c720401253 (192.168.241.22): Kernel does not exist: ce2c092f-f394-4b03-98ba-df9da361be68
[W 2025-10-18 11:46:28.935 ServerApp] 404 GET /api/kernels/ce2c092f-f394-4b03-98ba-df9da361be68/channels?session_id=82a95311-40a8-4a13-8c35-46c720401253 (d83dba3d5f47438d8a33fc3bbb8e9bfa@192.168.241.22) 1.38ms referer=None
[W 2025-10-18 11:46:28.946 ServerApp] 404 GET /api/kernels/ce2c092f-f394-4b03-98ba-df9da361be68?1760798788932 (192.168.241.22): Kernel does not exist: ce2c092f-f394-4b03-98ba-df9da361be68
[W 2025-10-18 11:46:28.946 ServerApp] wrote error: 'Kernel does not exist: ce2c092f-f394-4b03-98ba-df9da361be68'
    Traceback (most recent call last):
      File "/usr/local/lib64/python3.9/site-packages/tornado/web.py", line 1848, in _execute
        result = await result
      File "/usr/local/lib/python3.9/site-packages/jupyter_server/auth/decorator.py", line 73, in inner
        return await out
      File "/usr/local/lib/python3.9/site-packages/jupyter_server/services/kernels/handlers.py", line 75, in get
        model = await ensure_async(km.kernel_model(kernel_id))
      File "/usr/local/lib/python3.9/site-packages/jupyter_server/services/kernels/kernelmanager.py", line 513, in kernel_model
        self._check_kernel_id(kernel_id)
      File "/usr/local/lib/python3.9/site-packages/jupyter_server/services/kernels/kernelmanager.py", line 544, in _check_kernel_id
        raise web.HTTPError(404, "Kernel does not exist: %s" % kernel_id)
    tornado.web.HTTPError: HTTP 404: Not Found (Kernel does not exist: ce2c092f-f394-4b03-98ba-df9da361be68)
[W 2025-10-18 11:46:28.946 ServerApp] 404 GET /api/kernels/ce2c092f-f394-4b03-98ba-df9da361be68?1760798788932 (d83dba3d5f47438d8a33fc3bbb8e9bfa@192.168.241.22) 1.04ms referer=https://jupyter.pjc.mt.gov.br/notebooks/PEFT-LoRA/peft-lora.ipynb
