[I 2025-10-18 11:44:53.058 ServerApp] jupyter_lsp | extension was successfully linked.
[I 2025-10-18 11:44:53.061 ServerApp] jupyter_server_terminals | extension was successfully linked.
[I 2025-10-18 11:44:53.064 ServerApp] jupyterlab | extension was successfully linked.
[W 2025-10-18 11:44:53.065 JupyterNotebookApp] 'ip' has moved from NotebookApp to ServerApp. This config will be passed to ServerApp. Be sure to update your config before our next release.
[W 2025-10-18 11:44:53.066 JupyterNotebookApp] 'port' has moved from NotebookApp to ServerApp. This config will be passed to ServerApp. Be sure to update your config before our next release.
[W 2025-10-18 11:44:53.066 JupyterNotebookApp] 'port' has moved from NotebookApp to ServerApp. This config will be passed to ServerApp. Be sure to update your config before our next release.
[I 2025-10-18 11:44:53.068 ServerApp] notebook | extension was successfully linked.
[I 2025-10-18 11:44:53.236 ServerApp] notebook_shim | extension was successfully linked.
[I 2025-10-18 11:44:53.251 ServerApp] notebook_shim | extension was successfully loaded.
[I 2025-10-18 11:44:53.253 ServerApp] jupyter_lsp | extension was successfully loaded.
[I 2025-10-18 11:44:53.254 ServerApp] jupyter_server_terminals | extension was successfully loaded.
[I 2025-10-18 11:44:53.256 LabApp] JupyterLab extension loaded from /usr/local/lib/python3.9/site-packages/jupyterlab
[I 2025-10-18 11:44:53.256 LabApp] JupyterLab application directory is /usr/local/share/jupyter/lab
[I 2025-10-18 11:44:53.256 LabApp] Extension Manager is 'pypi'.
[I 2025-10-18 11:44:53.280 ServerApp] jupyterlab | extension was successfully loaded.
[I 2025-10-18 11:44:53.282 ServerApp] notebook | extension was successfully loaded.
[I 2025-10-18 11:44:53.283 ServerApp] Serving notebooks from local directory: /home/ricardo/fine-tuning-llm
[I 2025-10-18 11:44:53.283 ServerApp] Jupyter Server 2.17.0 is running at:
[I 2025-10-18 11:44:53.283 ServerApp] http://srv-pjc-ia:8888/tree
[I 2025-10-18 11:44:53.283 ServerApp]     http://127.0.0.1:8888/tree
[I 2025-10-18 11:44:53.283 ServerApp] Use Control-C to stop this server and shut down all kernels (twice to skip confirmation).
[I 2025-10-18 11:44:53.300 ServerApp] Skipped non-installed server(s): basedpyright, bash-language-server, dockerfile-language-server-nodejs, javascript-typescript-langserver, jedi-language-server, julia-language-server, pyrefly, pyright, python-language-server, python-lsp-server, r-languageserver, sql-language-server, texlab, typescript-language-server, unified-language-server, vscode-css-languageserver-bin, vscode-html-languageserver-bin, vscode-json-languageserver-bin, yaml-language-server
[W 2025-10-18 11:44:55.923 ServerApp] 404 GET /api/kernels/ce2c092f-f394-4b03-98ba-df9da361be68?1760798695905 (192.168.241.22): Kernel does not exist: ce2c092f-f394-4b03-98ba-df9da361be68
[W 2025-10-18 11:44:55.924 ServerApp] wrote error: 'Kernel does not exist: ce2c092f-f394-4b03-98ba-df9da361be68'
    Traceback (most recent call last):
      File "/usr/local/lib64/python3.9/site-packages/tornado/web.py", line 1848, in _execute
        result = await result
      File "/usr/local/lib/python3.9/site-packages/jupyter_server/auth/decorator.py", line 73, in inner
        return await out
      File "/usr/local/lib/python3.9/site-packages/jupyter_server/services/kernels/handlers.py", line 75, in get
        model = await ensure_async(km.kernel_model(kernel_id))
      File "/usr/local/lib/python3.9/site-packages/jupyter_server/services/kernels/kernelmanager.py", line 513, in kernel_model
        self._check_kernel_id(kernel_id)
      File "/usr/local/lib/python3.9/site-packages/jupyter_server/services/kernels/kernelmanager.py", line 544, in _check_kernel_id
        raise web.HTTPError(404, "Kernel does not exist: %s" % kernel_id)
    tornado.web.HTTPError: HTTP 404: Not Found (Kernel does not exist: ce2c092f-f394-4b03-98ba-df9da361be68)
[W 2025-10-18 11:44:55.926 ServerApp] 404 GET /api/kernels/ce2c092f-f394-4b03-98ba-df9da361be68?1760798695905 (d83dba3d5f47438d8a33fc3bbb8e9bfa@192.168.241.22) 3.44ms referer=https://jupyter.pjc.mt.gov.br/notebooks/PEFT-LoRA/peft-lora.ipynb
[W 2025-10-18 11:44:56.921 ServerApp] 404 GET /api/kernels/ce2c092f-f394-4b03-98ba-df9da361be68/channels?session_id=82a95311-40a8-4a13-8c35-46c720401253 (192.168.241.22): Kernel does not exist: ce2c092f-f394-4b03-98ba-df9da361be68
[W 2025-10-18 11:44:56.934 ServerApp] 404 GET /api/kernels/ce2c092f-f394-4b03-98ba-df9da361be68/channels?session_id=82a95311-40a8-4a13-8c35-46c720401253 (d83dba3d5f47438d8a33fc3bbb8e9bfa@192.168.241.22) 13.21ms referer=None
[W 2025-10-18 11:44:56.942 ServerApp] 404 GET /api/kernels/ce2c092f-f394-4b03-98ba-df9da361be68?1760798696931 (192.168.241.22): Kernel does not exist: ce2c092f-f394-4b03-98ba-df9da361be68
[W 2025-10-18 11:44:56.942 ServerApp] wrote error: 'Kernel does not exist: ce2c092f-f394-4b03-98ba-df9da361be68'
    Traceback (most recent call last):
      File "/usr/local/lib64/python3.9/site-packages/tornado/web.py", line 1848, in _execute
        result = await result
      File "/usr/local/lib/python3.9/site-packages/jupyter_server/auth/decorator.py", line 73, in inner
        return await out
      File "/usr/local/lib/python3.9/site-packages/jupyter_server/services/kernels/handlers.py", line 75, in get
        model = await ensure_async(km.kernel_model(kernel_id))
      File "/usr/local/lib/python3.9/site-packages/jupyter_server/services/kernels/kernelmanager.py", line 513, in kernel_model
        self._check_kernel_id(kernel_id)
      File "/usr/local/lib/python3.9/site-packages/jupyter_server/services/kernels/kernelmanager.py", line 544, in _check_kernel_id
        raise web.HTTPError(404, "Kernel does not exist: %s" % kernel_id)
    tornado.web.HTTPError: HTTP 404: Not Found (Kernel does not exist: ce2c092f-f394-4b03-98ba-df9da361be68)
[W 2025-10-18 11:44:56.942 ServerApp] 404 GET /api/kernels/ce2c092f-f394-4b03-98ba-df9da361be68?1760798696931 (d83dba3d5f47438d8a33fc3bbb8e9bfa@192.168.241.22) 1.12ms referer=https://jupyter.pjc.mt.gov.br/notebooks/PEFT-LoRA/peft-lora.ipynb
[W 2025-10-18 11:44:57.921 ServerApp] 404 GET /api/kernels/ce2c092f-f394-4b03-98ba-df9da361be68/channels?session_id=82a95311-40a8-4a13-8c35-46c720401253 (192.168.241.22): Kernel does not exist: ce2c092f-f394-4b03-98ba-df9da361be68
[W 2025-10-18 11:44:57.921 ServerApp] 404 GET /api/kernels/ce2c092f-f394-4b03-98ba-df9da361be68/channels?session_id=82a95311-40a8-4a13-8c35-46c720401253 (d83dba3d5f47438d8a33fc3bbb8e9bfa@192.168.241.22) 1.16ms referer=None
[W 2025-10-18 11:44:57.929 ServerApp] 404 GET /api/kernels/ce2c092f-f394-4b03-98ba-df9da361be68?1760798697918 (192.168.241.22): Kernel does not exist: ce2c092f-f394-4b03-98ba-df9da361be68
[W 2025-10-18 11:44:57.929 ServerApp] wrote error: 'Kernel does not exist: ce2c092f-f394-4b03-98ba-df9da361be68'
    Traceback (most recent call last):
      File "/usr/local/lib64/python3.9/site-packages/tornado/web.py", line 1848, in _execute
        result = await result
      File "/usr/local/lib/python3.9/site-packages/jupyter_server/auth/decorator.py", line 73, in inner
        return await out
      File "/usr/local/lib/python3.9/site-packages/jupyter_server/services/kernels/handlers.py", line 75, in get
        model = await ensure_async(km.kernel_model(kernel_id))
      File "/usr/local/lib/python3.9/site-packages/jupyter_server/services/kernels/kernelmanager.py", line 513, in kernel_model
        self._check_kernel_id(kernel_id)
      File "/usr/local/lib/python3.9/site-packages/jupyter_server/services/kernels/kernelmanager.py", line 544, in _check_kernel_id
        raise web.HTTPError(404, "Kernel does not exist: %s" % kernel_id)
    tornado.web.HTTPError: HTTP 404: Not Found (Kernel does not exist: ce2c092f-f394-4b03-98ba-df9da361be68)
[W 2025-10-18 11:44:57.929 ServerApp] 404 GET /api/kernels/ce2c092f-f394-4b03-98ba-df9da361be68?1760798697918 (d83dba3d5f47438d8a33fc3bbb8e9bfa@192.168.241.22) 0.91ms referer=https://jupyter.pjc.mt.gov.br/notebooks/PEFT-LoRA/peft-lora.ipynb
[W 2025-10-18 11:44:59.921 ServerApp] 404 GET /api/kernels/ce2c092f-f394-4b03-98ba-df9da361be68/channels?session_id=82a95311-40a8-4a13-8c35-46c720401253 (192.168.241.22): Kernel does not exist: ce2c092f-f394-4b03-98ba-df9da361be68
[W 2025-10-18 11:44:59.922 ServerApp] 404 GET /api/kernels/ce2c092f-f394-4b03-98ba-df9da361be68/channels?session_id=82a95311-40a8-4a13-8c35-46c720401253 (d83dba3d5f47438d8a33fc3bbb8e9bfa@192.168.241.22) 1.60ms referer=None
[W 2025-10-18 11:44:59.932 ServerApp] 404 GET /api/kernels/ce2c092f-f394-4b03-98ba-df9da361be68?1760798699919 (192.168.241.22): Kernel does not exist: ce2c092f-f394-4b03-98ba-df9da361be68
[W 2025-10-18 11:44:59.932 ServerApp] wrote error: 'Kernel does not exist: ce2c092f-f394-4b03-98ba-df9da361be68'
    Traceback (most recent call last):
      File "/usr/local/lib64/python3.9/site-packages/tornado/web.py", line 1848, in _execute
        result = await result
      File "/usr/local/lib/python3.9/site-packages/jupyter_server/auth/decorator.py", line 73, in inner
        return await out
      File "/usr/local/lib/python3.9/site-packages/jupyter_server/services/kernels/handlers.py", line 75, in get
        model = await ensure_async(km.kernel_model(kernel_id))
      File "/usr/local/lib/python3.9/site-packages/jupyter_server/services/kernels/kernelmanager.py", line 513, in kernel_model
        self._check_kernel_id(kernel_id)
      File "/usr/local/lib/python3.9/site-packages/jupyter_server/services/kernels/kernelmanager.py", line 544, in _check_kernel_id
        raise web.HTTPError(404, "Kernel does not exist: %s" % kernel_id)
    tornado.web.HTTPError: HTTP 404: Not Found (Kernel does not exist: ce2c092f-f394-4b03-98ba-df9da361be68)
[W 2025-10-18 11:44:59.932 ServerApp] 404 GET /api/kernels/ce2c092f-f394-4b03-98ba-df9da361be68?1760798699919 (d83dba3d5f47438d8a33fc3bbb8e9bfa@192.168.241.22) 1.20ms referer=https://jupyter.pjc.mt.gov.br/notebooks/PEFT-LoRA/peft-lora.ipynb
[W 2025-10-18 11:45:14.931 ServerApp] 404 GET /api/kernels/ce2c092f-f394-4b03-98ba-df9da361be68/channels?session_id=82a95311-40a8-4a13-8c35-46c720401253 (192.168.241.22): Kernel does not exist: ce2c092f-f394-4b03-98ba-df9da361be68
[W 2025-10-18 11:45:14.932 ServerApp] 404 GET /api/kernels/ce2c092f-f394-4b03-98ba-df9da361be68/channels?session_id=82a95311-40a8-4a13-8c35-46c720401253 (d83dba3d5f47438d8a33fc3bbb8e9bfa@192.168.241.22) 1.38ms referer=None
[W 2025-10-18 11:45:14.939 ServerApp] 404 GET /api/kernels/ce2c092f-f394-4b03-98ba-df9da361be68?1760798714928 (192.168.241.22): Kernel does not exist: ce2c092f-f394-4b03-98ba-df9da361be68
[W 2025-10-18 11:45:14.939 ServerApp] wrote error: 'Kernel does not exist: ce2c092f-f394-4b03-98ba-df9da361be68'
    Traceback (most recent call last):
      File "/usr/local/lib64/python3.9/site-packages/tornado/web.py", line 1848, in _execute
        result = await result
      File "/usr/local/lib/python3.9/site-packages/jupyter_server/auth/decorator.py", line 73, in inner
        return await out
      File "/usr/local/lib/python3.9/site-packages/jupyter_server/services/kernels/handlers.py", line 75, in get
        model = await ensure_async(km.kernel_model(kernel_id))
      File "/usr/local/lib/python3.9/site-packages/jupyter_server/services/kernels/kernelmanager.py", line 513, in kernel_model
        self._check_kernel_id(kernel_id)
      File "/usr/local/lib/python3.9/site-packages/jupyter_server/services/kernels/kernelmanager.py", line 544, in _check_kernel_id
        raise web.HTTPError(404, "Kernel does not exist: %s" % kernel_id)
    tornado.web.HTTPError: HTTP 404: Not Found (Kernel does not exist: ce2c092f-f394-4b03-98ba-df9da361be68)
[W 2025-10-18 11:45:14.940 ServerApp] 404 GET /api/kernels/ce2c092f-f394-4b03-98ba-df9da361be68?1760798714928 (d83dba3d5f47438d8a33fc3bbb8e9bfa@192.168.241.22) 1.11ms referer=https://jupyter.pjc.mt.gov.br/notebooks/PEFT-LoRA/peft-lora.ipynb
[W 2025-10-18 11:45:33.933 ServerApp] 404 GET /api/kernels/ce2c092f-f394-4b03-98ba-df9da361be68/channels?session_id=82a95311-40a8-4a13-8c35-46c720401253 (192.168.241.22): Kernel does not exist: ce2c092f-f394-4b03-98ba-df9da361be68
[W 2025-10-18 11:45:33.933 ServerApp] 404 GET /api/kernels/ce2c092f-f394-4b03-98ba-df9da361be68/channels?session_id=82a95311-40a8-4a13-8c35-46c720401253 (d83dba3d5f47438d8a33fc3bbb8e9bfa@192.168.241.22) 1.27ms referer=None
[W 2025-10-18 11:45:33.940 ServerApp] 404 GET /api/kernels/ce2c092f-f394-4b03-98ba-df9da361be68?1760798733930 (192.168.241.22): Kernel does not exist: ce2c092f-f394-4b03-98ba-df9da361be68
[W 2025-10-18 11:45:33.941 ServerApp] wrote error: 'Kernel does not exist: ce2c092f-f394-4b03-98ba-df9da361be68'
    Traceback (most recent call last):
      File "/usr/local/lib64/python3.9/site-packages/tornado/web.py", line 1848, in _execute
        result = await result
      File "/usr/local/lib/python3.9/site-packages/jupyter_server/auth/decorator.py", line 73, in inner
        return await out
      File "/usr/local/lib/python3.9/site-packages/jupyter_server/services/kernels/handlers.py", line 75, in get
        model = await ensure_async(km.kernel_model(kernel_id))
      File "/usr/local/lib/python3.9/site-packages/jupyter_server/services/kernels/kernelmanager.py", line 513, in kernel_model
        self._check_kernel_id(kernel_id)
      File "/usr/local/lib/python3.9/site-packages/jupyter_server/services/kernels/kernelmanager.py", line 544, in _check_kernel_id
        raise web.HTTPError(404, "Kernel does not exist: %s" % kernel_id)
    tornado.web.HTTPError: HTTP 404: Not Found (Kernel does not exist: ce2c092f-f394-4b03-98ba-df9da361be68)
[W 2025-10-18 11:45:33.941 ServerApp] 404 GET /api/kernels/ce2c092f-f394-4b03-98ba-df9da361be68?1760798733930 (d83dba3d5f47438d8a33fc3bbb8e9bfa@192.168.241.22) 0.96ms referer=https://jupyter.pjc.mt.gov.br/notebooks/PEFT-LoRA/peft-lora.ipynb
[W 2025-10-18 11:46:28.934 ServerApp] 404 GET /api/kernels/ce2c092f-f394-4b03-98ba-df9da361be68/channels?session_id=82a95311-40a8-4a13-8c35-46c720401253 (192.168.241.22): Kernel does not exist: ce2c092f-f394-4b03-98ba-df9da361be68
[W 2025-10-18 11:46:28.935 ServerApp] 404 GET /api/kernels/ce2c092f-f394-4b03-98ba-df9da361be68/channels?session_id=82a95311-40a8-4a13-8c35-46c720401253 (d83dba3d5f47438d8a33fc3bbb8e9bfa@192.168.241.22) 1.38ms referer=None
[W 2025-10-18 11:46:28.946 ServerApp] 404 GET /api/kernels/ce2c092f-f394-4b03-98ba-df9da361be68?1760798788932 (192.168.241.22): Kernel does not exist: ce2c092f-f394-4b03-98ba-df9da361be68
[W 2025-10-18 11:46:28.946 ServerApp] wrote error: 'Kernel does not exist: ce2c092f-f394-4b03-98ba-df9da361be68'
    Traceback (most recent call last):
      File "/usr/local/lib64/python3.9/site-packages/tornado/web.py", line 1848, in _execute
        result = await result
      File "/usr/local/lib/python3.9/site-packages/jupyter_server/auth/decorator.py", line 73, in inner
        return await out
      File "/usr/local/lib/python3.9/site-packages/jupyter_server/services/kernels/handlers.py", line 75, in get
        model = await ensure_async(km.kernel_model(kernel_id))
      File "/usr/local/lib/python3.9/site-packages/jupyter_server/services/kernels/kernelmanager.py", line 513, in kernel_model
        self._check_kernel_id(kernel_id)
      File "/usr/local/lib/python3.9/site-packages/jupyter_server/services/kernels/kernelmanager.py", line 544, in _check_kernel_id
        raise web.HTTPError(404, "Kernel does not exist: %s" % kernel_id)
    tornado.web.HTTPError: HTTP 404: Not Found (Kernel does not exist: ce2c092f-f394-4b03-98ba-df9da361be68)
[W 2025-10-18 11:46:28.946 ServerApp] 404 GET /api/kernels/ce2c092f-f394-4b03-98ba-df9da361be68?1760798788932 (d83dba3d5f47438d8a33fc3bbb8e9bfa@192.168.241.22) 1.04ms referer=https://jupyter.pjc.mt.gov.br/notebooks/PEFT-LoRA/peft-lora.ipynb
[I 2025-10-18 11:54:51.695 ServerApp] Kernel started: 8c9a5913-4591-4dfa-bc32-dc336c07df4c
[I 2025-10-18 11:54:52.059 ServerApp] Connecting to kernel 8c9a5913-4591-4dfa-bc32-dc336c07df4c.
[W 2025-10-18 11:54:52.061 ServerApp] The websocket_ping_timeout (90000) cannot be longer than the websocket_ping_interval (30000).
    Setting websocket_ping_timeout=30000
[I 2025-10-18 11:54:52.108 ServerApp] Starting buffering for 8c9a5913-4591-4dfa-bc32-dc336c07df4c:fb2cc8ca-3983-488c-99c1-b2f9e54f3946
[I 2025-10-18 11:54:52.135 ServerApp] Connecting to kernel 8c9a5913-4591-4dfa-bc32-dc336c07df4c.
[I 2025-10-18 11:54:52.218 ServerApp] Connecting to kernel 8c9a5913-4591-4dfa-bc32-dc336c07df4c.
[I 2025-10-18 11:54:54.812 ServerApp] Connecting to kernel 8c9a5913-4591-4dfa-bc32-dc336c07df4c.
[I 2025-10-18 11:56:51.588 ServerApp] Saving file at /PEFT-PT/peft-pt.ipynb
[I 2025-10-18 11:58:51.699 ServerApp] Saving file at /PEFT-PT/peft-pt.ipynb
[I 2025-10-18 12:00:51.799 ServerApp] Saving file at /PEFT-PT/peft-pt.ipynb
[I 2025-10-18 12:02:51.903 ServerApp] Saving file at /PEFT-PT/peft-pt.ipynb
[I 2025-10-18 12:04:52.015 ServerApp] Saving file at /PEFT-PT/peft-pt.ipynb
[I 2025-10-18 12:06:04.116 ServerApp] Kernel interrupted: 8c9a5913-4591-4dfa-bc32-dc336c07df4c
[I 2025-10-18 12:06:14.510 ServerApp] Kernel started: 5ce4a01a-2d1c-46e7-8332-cb4fccb4d487
[I 2025-10-18 12:06:14.512 ServerApp] Kernel shutdown: 8c9a5913-4591-4dfa-bc32-dc336c07df4c
[I 2025-10-18 12:06:14.876 ServerApp] Connecting to kernel 5ce4a01a-2d1c-46e7-8332-cb4fccb4d487.
[I 2025-10-18 12:06:53.097 ServerApp] Saving file at /PEFT-PT/peft-pt.ipynb
[I 2025-10-18 12:08:53.193 ServerApp] Saving file at /PEFT-PT/peft-pt.ipynb
[I 2025-10-18 12:12:53.607 ServerApp] Saving file at /PEFT-PT/peft-pt.ipynb
[I 2025-10-18 12:15:44.025 ServerApp] Connecting to kernel 5ce4a01a-2d1c-46e7-8332-cb4fccb4d487.
[W 2025-10-18 12:15:44.046 LabApp] Could not determine jupyterlab build status without nodejs
[W 2025-10-18 12:15:44.266 ServerApp] 404 GET /api/contents/ft_kd?content=0&hash=0&1760800544225 (4e44c18e31e34792b64931a8b1f18873@192.168.241.22) 1.07ms referer=https://jupyter.pjc.mt.gov.br/doc/tree/PEFT-PT/peft-pt.ipynb
[W 2025-10-18 12:15:44.266 ServerApp] 404 GET /api/contents/ft_kd?content=0&hash=0&1760800544225 (192.168.241.22): No such file or directory: ft_kd
[W 2025-10-18 12:15:44.267 ServerApp] 404 GET /api/contents/ft_kd/gmn_kd_qwen3b.ipynb?content=0&hash=0&1760800544225 (4e44c18e31e34792b64931a8b1f18873@192.168.241.22) 0.68ms referer=https://jupyter.pjc.mt.gov.br/doc/tree/PEFT-PT/peft-pt.ipynb
[W 2025-10-18 12:15:44.267 ServerApp] 404 GET /api/contents/ft_kd/gmn_kd_qwen3b.ipynb?content=0&hash=0&1760800544225 (192.168.241.22): No such file or directory: ft_kd/gmn_kd_qwen3b.ipynb
[I 2025-10-18 12:15:45.726 ServerApp] Connecting to kernel 5ce4a01a-2d1c-46e7-8332-cb4fccb4d487.
[I 2025-10-18 12:17:44.388 ServerApp] Kernel interrupted: 5ce4a01a-2d1c-46e7-8332-cb4fccb4d487
[I 2025-10-18 12:17:45.780 ServerApp] Kernel interrupted: 5ce4a01a-2d1c-46e7-8332-cb4fccb4d487
[I 2025-10-18 12:17:45.970 ServerApp] Kernel interrupted: 5ce4a01a-2d1c-46e7-8332-cb4fccb4d487
[I 2025-10-18 12:17:46.154 ServerApp] Kernel interrupted: 5ce4a01a-2d1c-46e7-8332-cb4fccb4d487
[I 2025-10-18 12:17:57.726 ServerApp] Kernel shutdown: 5ce4a01a-2d1c-46e7-8332-cb4fccb4d487
[I 2025-10-18 12:18:33.225 ServerApp] Kernel started: 3b40394d-94b1-4332-97ff-3970f0734799
[I 2025-10-18 12:18:33.654 ServerApp] Connecting to kernel 3b40394d-94b1-4332-97ff-3970f0734799.
[I 2025-10-18 12:18:41.437 ServerApp] Kernel started: d1a54a90-10e7-4348-bb85-0f4984c72b7c
[I 2025-10-18 12:18:41.439 ServerApp] Kernel shutdown: 3b40394d-94b1-4332-97ff-3970f0734799
[I 2025-10-18 12:18:41.788 ServerApp] Connecting to kernel d1a54a90-10e7-4348-bb85-0f4984c72b7c.
[I 2025-10-18 12:18:44.949 ServerApp] Kernel interrupted: d1a54a90-10e7-4348-bb85-0f4984c72b7c
[I 2025-10-18 12:18:58.946 ServerApp] Starting buffering for d1a54a90-10e7-4348-bb85-0f4984c72b7c:ba69e9b3-279f-4436-ac43-0906e249fcba
[I 2025-10-18 12:18:59.038 ServerApp] Connecting to kernel d1a54a90-10e7-4348-bb85-0f4984c72b7c.
[I 2025-10-18 12:18:59.038 ServerApp] Restoring connection for d1a54a90-10e7-4348-bb85-0f4984c72b7c:ba69e9b3-279f-4436-ac43-0906e249fcba
[I 2025-10-18 12:18:59.065 ServerApp] Starting buffering for d1a54a90-10e7-4348-bb85-0f4984c72b7c:ba69e9b3-279f-4436-ac43-0906e249fcba
[I 2025-10-18 12:18:59.800 ServerApp] Connecting to kernel d1a54a90-10e7-4348-bb85-0f4984c72b7c.
[I 2025-10-18 12:18:59.847 ServerApp] Starting buffering for d1a54a90-10e7-4348-bb85-0f4984c72b7c:7f9ad351-9734-4636-a51a-da1557092078
[W 2025-10-18 12:18:59.856 LabApp] Could not determine jupyterlab build status without nodejs
[I 2025-10-18 12:19:01.540 ServerApp] Connecting to kernel d1a54a90-10e7-4348-bb85-0f4984c72b7c.
[I 2025-10-18 12:19:05.689 ServerApp] Kernel shutdown: d1a54a90-10e7-4348-bb85-0f4984c72b7c
[I 2025-10-18 12:19:13.271 ServerApp] Kernel started: 95788a0f-a698-49a1-af30-30bf6099caea
[I 2025-10-18 12:19:13.650 ServerApp] Connecting to kernel 95788a0f-a698-49a1-af30-30bf6099caea.
[I 2025-10-18 12:21:01.397 ServerApp] Saving file at /PEFT-PT/peft-pt.ipynb
[I 2025-10-18 12:23:01.548 ServerApp] Saving file at /PEFT-PT/peft-pt.ipynb
[I 2025-10-18 12:25:01.906 ServerApp] Saving file at /PEFT-PT/peft-pt.ipynb
[I 2025-10-18 14:17:02.090 ServerApp] Saving file at /PEFT-PT/peft-pt.ipynb
[I 2025-10-18 14:19:02.409 ServerApp] Saving file at /PEFT-PT/peft-pt.ipynb
[I 2025-10-18 14:19:34.829 ServerApp] Kernel shutdown: 95788a0f-a698-49a1-af30-30bf6099caea
[I 2025-10-18 14:19:42.846 ServerApp] Creating new notebook in /PEFT-PT
[I 2025-10-18 14:19:50.490 ServerApp] Kernel started: 61cff716-784e-4736-9222-2cd0d03b6694
[I 2025-10-18 14:19:50.848 ServerApp] Connecting to kernel 61cff716-784e-4736-9222-2cd0d03b6694.
[I 2025-10-18 14:19:50.899 ServerApp] Starting buffering for 61cff716-784e-4736-9222-2cd0d03b6694:8a24be22-e482-40db-a853-440e5c9b1e9c
[I 2025-10-18 14:19:50.924 ServerApp] Connecting to kernel 61cff716-784e-4736-9222-2cd0d03b6694.
[I 2025-10-18 14:19:50.995 ServerApp] Connecting to kernel 61cff716-784e-4736-9222-2cd0d03b6694.
[I 2025-10-18 14:19:57.692 ServerApp] Starting buffering for 61cff716-784e-4736-9222-2cd0d03b6694:30ec24a1-b0e8-4df7-bbee-8622e1bb7b60
[I 2025-10-18 14:20:02.078 ServerApp] Kernel shutdown: 61cff716-784e-4736-9222-2cd0d03b6694
[W 2025-10-18 14:20:22.023 ServerApp] delete /PEFT-PT/Untitled.ipynb
[I 2025-10-18 14:20:25.407 ServerApp] Copying 'PEFT-PT/peft-pt.ipynb' to '/PEFT-PT'
[I 2025-10-18 14:21:35.751 ServerApp] Kernel started: f65cccaa-1e71-474f-bbca-b3760f5d87c6
[I 2025-10-18 14:21:36.192 ServerApp] Connecting to kernel f65cccaa-1e71-474f-bbca-b3760f5d87c6.
[I 2025-10-18 14:21:36.243 ServerApp] Starting buffering for f65cccaa-1e71-474f-bbca-b3760f5d87c6:a5d0ffaa-e438-4b29-b358-2c8a5afb4c17
[I 2025-10-18 14:21:36.268 ServerApp] Connecting to kernel f65cccaa-1e71-474f-bbca-b3760f5d87c6.
[I 2025-10-18 14:21:36.353 ServerApp] Connecting to kernel f65cccaa-1e71-474f-bbca-b3760f5d87c6.
[I 2025-10-18 14:22:11.193 ServerApp] Connecting to kernel f65cccaa-1e71-474f-bbca-b3760f5d87c6.
[I 2025-10-18 14:23:35.593 ServerApp] Saving file at /PEFT-PT/peft-pt-2.ipynb
[I 2025-10-18 14:25:35.713 ServerApp] Saving file at /PEFT-PT/peft-pt-2.ipynb
[I 2025-10-18 14:27:35.857 ServerApp] Saving file at /PEFT-PT/peft-pt-2.ipynb
[I 2025-10-18 14:29:28.108 ServerApp] Kernel interrupted: f65cccaa-1e71-474f-bbca-b3760f5d87c6
[I 2025-10-18 14:29:34.645 ServerApp] Kernel started: 3eaef20b-06e6-4e53-97ef-5f21dfc2f100
[I 2025-10-18 14:29:34.647 ServerApp] Kernel shutdown: f65cccaa-1e71-474f-bbca-b3760f5d87c6
[I 2025-10-18 14:29:35.018 ServerApp] Connecting to kernel 3eaef20b-06e6-4e53-97ef-5f21dfc2f100.
[I 2025-10-18 14:29:35.980 ServerApp] Saving file at /PEFT-PT/peft-pt-2.ipynb
  [2m2025-10-18T17:30:16.946163Z[0m [31mERROR[0m  [31mPython exception updating progress:, error: PyErr { type: <class 'LookupError'>, value: LookupError(<ContextVar name='shell_parent' at 0x7ff4b6de6c00>), traceback: Some(<traceback object at 0x7ff3bff5f740>) }, [1;31mcaller[0m[31m: "src/progress_update.rs:313"[0m
    [2;3mat[0m /home/runner/work/xet-core/xet-core/error_printer/src/lib.rs:28

[I 2025-10-18 14:31:36.089 ServerApp] Saving file at /PEFT-PT/peft-pt-2.ipynb
[I 2025-10-18 14:31:38.096 ServerApp] Kernel interrupted: 3eaef20b-06e6-4e53-97ef-5f21dfc2f100
Cancellation requested; stopping current tasks.
[I 2025-10-18 14:31:42.527 ServerApp] Kernel interrupted: 3eaef20b-06e6-4e53-97ef-5f21dfc2f100
[I 2025-10-18 14:33:36.197 ServerApp] Saving file at /PEFT-PT/peft-pt-2.ipynb
[I 2025-10-18 14:33:40.364 ServerApp] Kernel interrupted: 3eaef20b-06e6-4e53-97ef-5f21dfc2f100
[I 2025-10-18 14:33:49.509 ServerApp] Kernel interrupted: 3eaef20b-06e6-4e53-97ef-5f21dfc2f100
[I 2025-10-18 14:34:00.538 ServerApp] Kernel shutdown: 3eaef20b-06e6-4e53-97ef-5f21dfc2f100
[I 2025-10-18 14:34:09.856 ServerApp] Kernel started: 04763547-8a33-41f4-9b48-cf5d032f0b73
[I 2025-10-18 14:34:10.298 ServerApp] Connecting to kernel 04763547-8a33-41f4-9b48-cf5d032f0b73.
[I 2025-10-18 14:34:13.365 ServerApp] Kernel interrupted: 04763547-8a33-41f4-9b48-cf5d032f0b73
[I 2025-10-18 14:34:26.185 ServerApp] Starting buffering for 04763547-8a33-41f4-9b48-cf5d032f0b73:e35bfb89-4d71-4941-9404-c9c838f89e90
[I 2025-10-18 14:34:26.263 ServerApp] Connecting to kernel 04763547-8a33-41f4-9b48-cf5d032f0b73.
[I 2025-10-18 14:34:26.263 ServerApp] Restoring connection for 04763547-8a33-41f4-9b48-cf5d032f0b73:e35bfb89-4d71-4941-9404-c9c838f89e90
[I 2025-10-18 14:34:26.285 ServerApp] Starting buffering for 04763547-8a33-41f4-9b48-cf5d032f0b73:e35bfb89-4d71-4941-9404-c9c838f89e90
[I 2025-10-18 14:34:27.231 ServerApp] Connecting to kernel 04763547-8a33-41f4-9b48-cf5d032f0b73.
[I 2025-10-18 14:34:27.438 ServerApp] Starting buffering for 04763547-8a33-41f4-9b48-cf5d032f0b73:c0c8e16c-cbe9-49cb-861b-2fce2c12b8b6
[I 2025-10-18 14:34:27.677 ServerApp] Connecting to kernel 04763547-8a33-41f4-9b48-cf5d032f0b73.
  [2m2025-10-18T17:36:01.782643Z[0m [31mERROR[0m  [31mPython exception updating progress:, error: PyErr { type: <class 'LookupError'>, value: LookupError(<ContextVar name='shell_parent' at 0x7f8eac246480>), traceback: Some(<traceback object at 0x7f8da83d7b80>) }, [1;31mcaller[0m[31m: "src/progress_update.rs:313"[0m
    [2;3mat[0m /home/runner/work/xet-core/xet-core/error_printer/src/lib.rs:28

[I 2025-10-18 14:36:27.781 ServerApp] Saving file at /PEFT-PT/peft-pt-2.ipynb
[I 2025-10-18 14:38:27.920 ServerApp] Saving file at /PEFT-PT/peft-pt-2.ipynb
[I 2025-10-18 14:40:28.058 ServerApp] Saving file at /PEFT-PT/peft-pt-2.ipynb
[I 2025-10-18 14:44:28.200 ServerApp] Saving file at /PEFT-PT/peft-pt-2.ipynb
[I 2025-10-18 14:49:05.876 ServerApp] Creating new directory in 
[I 2025-10-18 14:55:40.425 ServerApp] Creating new notebook in /PEFT-QLoRA-Axolotl
[I 2025-10-18 14:55:41.684 ServerApp] Connecting to kernel 04763547-8a33-41f4-9b48-cf5d032f0b73.
[I 2025-10-18 14:55:50.486 ServerApp] Connecting to kernel 04763547-8a33-41f4-9b48-cf5d032f0b73.
[I 2025-10-18 14:58:07.727 ServerApp] Saving file at /PEFT-QLoRA-Axolotl/peft-qLoRA-Axolotl.ipynb
[I 2025-10-18 14:59:38.842 ServerApp] Creating new file in /PEFT-QLoRA-Axolotl
[I 2025-10-18 14:59:54.322 ServerApp] Connecting to kernel 04763547-8a33-41f4-9b48-cf5d032f0b73.
[I 2025-10-18 15:00:08.702 ServerApp] Saving file at /PEFT-QLoRA-Axolotl/peft-qLoRA-Axolotl.ipynb
[I 2025-10-18 15:01:54.409 ServerApp] Saving file at /PEFT-QLoRA-Axolotl/config_qlora.yml
[I 2025-10-18 15:02:47.789 ServerApp] Saving file at /PEFT-QLoRA-Axolotl/config_qlora.yml
[I 2025-10-18 15:04:08.906 ServerApp] Saving file at /PEFT-QLoRA-Axolotl/peft-qLoRA-Axolotl.ipynb
[I 2025-10-18 15:06:09.001 ServerApp] Saving file at /PEFT-QLoRA-Axolotl/peft-qLoRA-Axolotl.ipynb
[I 2025-10-18 15:08:04.373 ServerApp] Kernel interrupted: 04763547-8a33-41f4-9b48-cf5d032f0b73
Cancellation requested; stopping current tasks.
[I 2025-10-18 15:08:05.349 ServerApp] Kernel interrupted: 04763547-8a33-41f4-9b48-cf5d032f0b73
[I 2025-10-18 15:08:10.103 ServerApp] Kernel restarted: 04763547-8a33-41f4-9b48-cf5d032f0b73
[I 2025-10-18 15:08:10.128 ServerApp] Starting buffering for 04763547-8a33-41f4-9b48-cf5d032f0b73:666ea692-fe54-4de1-8104-1778e617dbd7
[I 2025-10-18 15:08:10.194 ServerApp] Connecting to kernel 04763547-8a33-41f4-9b48-cf5d032f0b73.
[I 2025-10-18 15:08:10.194 ServerApp] Restoring connection for 04763547-8a33-41f4-9b48-cf5d032f0b73:666ea692-fe54-4de1-8104-1778e617dbd7
[I 2025-10-18 15:08:36.297 ServerApp] Saving file at /PEFT-PT/peft-pt-2.ipynb
[I 2025-10-18 15:10:38.613 ServerApp] Kernel started: e1404771-63a0-436c-a7e5-d44e6258a1e8
[I 2025-10-18 15:10:38.615 ServerApp] Kernel shutdown: 04763547-8a33-41f4-9b48-cf5d032f0b73
[I 2025-10-18 15:10:39.018 ServerApp] Connecting to kernel e1404771-63a0-436c-a7e5-d44e6258a1e8.
[I 2025-10-18 15:12:36.449 ServerApp] Saving file at /PEFT-PT/peft-pt-2.ipynb
[I 2025-10-18 15:14:36.603 ServerApp] Saving file at /PEFT-PT/peft-pt-2.ipynb
[I 2025-10-18 15:16:36.741 ServerApp] Saving file at /PEFT-PT/peft-pt-2.ipynb
[I 2025-10-18 15:18:36.940 ServerApp] Saving file at /PEFT-PT/peft-pt-2.ipynb
[I 2025-10-18 15:22:21.433 ServerApp] Kernel interrupted: e1404771-63a0-436c-a7e5-d44e6258a1e8
[I 2025-10-18 15:22:25.486 ServerApp] Kernel restarted: e1404771-63a0-436c-a7e5-d44e6258a1e8
[I 2025-10-18 15:22:25.510 ServerApp] Starting buffering for e1404771-63a0-436c-a7e5-d44e6258a1e8:666ea692-fe54-4de1-8104-1778e617dbd7
[I 2025-10-18 15:22:25.584 ServerApp] Connecting to kernel e1404771-63a0-436c-a7e5-d44e6258a1e8.
[I 2025-10-18 15:22:25.584 ServerApp] Restoring connection for e1404771-63a0-436c-a7e5-d44e6258a1e8:666ea692-fe54-4de1-8104-1778e617dbd7
[I 2025-10-18 15:22:37.094 ServerApp] Saving file at /PEFT-PT/peft-pt-2.ipynb
[I 2025-10-18 15:24:37.243 ServerApp] Saving file at /PEFT-PT/peft-pt-2.ipynb
[I 2025-10-18 15:26:27.407 ServerApp] Connecting to kernel e1404771-63a0-436c-a7e5-d44e6258a1e8.
[I 2025-10-18 15:26:37.395 ServerApp] Saving file at /PEFT-PT/peft-pt-2.ipynb
[I 2025-10-18 15:28:37.549 ServerApp] Saving file at /PEFT-PT/peft-pt-2.ipynb
  [2m2025-10-18T18:29:19.438150Z[0m [31mERROR[0m  [31mPython exception updating progress:, error: PyErr { type: <class 'LookupError'>, value: LookupError(<ContextVar name='shell_parent' at 0x7ff20c1d67f0>), traceback: Some(<traceback object at 0x7ff1020edb40>) }, [1;31mcaller[0m[31m: "src/progress_update.rs:313"[0m
    [2;3mat[0m /home/runner/work/xet-core/xet-core/error_printer/src/lib.rs:28

[I 2025-10-18 15:30:37.709 ServerApp] Saving file at /PEFT-PT/peft-pt-2.ipynb
[I 2025-10-18 15:31:02.040 ServerApp] Kernel interrupted: e1404771-63a0-436c-a7e5-d44e6258a1e8
Cancellation requested; stopping current tasks.
[E 2025-10-18 15:31:06.280 ServerApp] Uncaught exception POST /api/kernels/e1404771-63a0-436c-a7e5-d44e6258a1e8/interrupt?1760812266261 (192.168.241.22)
    HTTPServerRequest(protocol='http', host='jupyter.pjc.mt.gov.br', method='POST', uri='/api/kernels/e1404771-63a0-436c-a7e5-d44e6258a1e8/interrupt?1760812266261', version='HTTP/1.1', remote_ip='192.168.241.22')
    Traceback (most recent call last):
      File "/usr/local/lib64/python3.9/site-packages/tornado/web.py", line 1848, in _execute
        result = await result
      File "/usr/local/lib/python3.9/site-packages/jupyter_server/auth/decorator.py", line 73, in inner
        return await out
      File "/usr/local/lib/python3.9/site-packages/jupyter_server/services/kernels/handlers.py", line 97, in post
        await ensure_async(km.interrupt_kernel(kernel_id))  # type:ignore[func-returns-value]
      File "/usr/local/lib/python3.9/site-packages/jupyter_client/multikernelmanager.py", line 395, in interrupt_kernel
        raise RuntimeError(msg)
    RuntimeError: Kernel is in a pending state. Cannot interrupt.
[W 2025-10-18 15:31:06.281 ServerApp] wrote error: 'Unhandled error'
    Traceback (most recent call last):
      File "/usr/local/lib64/python3.9/site-packages/tornado/web.py", line 1848, in _execute
        result = await result
      File "/usr/local/lib/python3.9/site-packages/jupyter_server/auth/decorator.py", line 73, in inner
        return await out
      File "/usr/local/lib/python3.9/site-packages/jupyter_server/services/kernels/handlers.py", line 97, in post
        await ensure_async(km.interrupt_kernel(kernel_id))  # type:ignore[func-returns-value]
      File "/usr/local/lib/python3.9/site-packages/jupyter_client/multikernelmanager.py", line 395, in interrupt_kernel
        raise RuntimeError(msg)
    RuntimeError: Kernel is in a pending state. Cannot interrupt.
[E 2025-10-18 15:31:06.281 ServerApp] {
      "Host": "jupyter.pjc.mt.gov.br",
      "Accept": "*/*",
      "Referer": "https://jupyter.pjc.mt.gov.br/notebooks/PEFT-PT/peft-pt-2.ipynb",
      "User-Agent": "Mozilla/5.0 (X11; Linux x86_64; rv:143.0) Gecko/20100101 Firefox/143.0"
    }
[E 2025-10-18 15:31:06.282 ServerApp] 500 POST /api/kernels/e1404771-63a0-436c-a7e5-d44e6258a1e8/interrupt?1760812266261 (4e44c18e31e34792b64931a8b1f18873@192.168.241.22) 2.09ms referer=https://jupyter.pjc.mt.gov.br/notebooks/PEFT-PT/peft-pt-2.ipynb
[I 2025-10-18 15:31:07.124 ServerApp] Kernel restarted: e1404771-63a0-436c-a7e5-d44e6258a1e8
[I 2025-10-18 15:31:07.154 ServerApp] Starting buffering for e1404771-63a0-436c-a7e5-d44e6258a1e8:666ea692-fe54-4de1-8104-1778e617dbd7
[I 2025-10-18 15:31:07.210 ServerApp] Connecting to kernel e1404771-63a0-436c-a7e5-d44e6258a1e8.
[I 2025-10-18 15:31:07.210 ServerApp] Restoring connection for e1404771-63a0-436c-a7e5-d44e6258a1e8:666ea692-fe54-4de1-8104-1778e617dbd7
[I 2025-10-18 15:31:08.389 ServerApp] Kernel restarted: e1404771-63a0-436c-a7e5-d44e6258a1e8
[I 2025-10-18 15:31:08.419 ServerApp] Starting buffering for e1404771-63a0-436c-a7e5-d44e6258a1e8:666ea692-fe54-4de1-8104-1778e617dbd7
[I 2025-10-18 15:31:08.477 ServerApp] Connecting to kernel e1404771-63a0-436c-a7e5-d44e6258a1e8.
[I 2025-10-18 15:31:08.477 ServerApp] Restoring connection for e1404771-63a0-436c-a7e5-d44e6258a1e8:666ea692-fe54-4de1-8104-1778e617dbd7
  [2m2025-10-18T18:31:29.396053Z[0m [31mERROR[0m  [31mPython exception updating progress:, error: PyErr { type: <class 'LookupError'>, value: LookupError(<ContextVar name='shell_parent' at 0x7f953f49a840>), traceback: Some(<traceback object at 0x7f9459ad32c0>) }, [1;31mcaller[0m[31m: "src/progress_update.rs:313"[0m
    [2;3mat[0m /home/runner/work/xet-core/xet-core/error_printer/src/lib.rs:28

[I 2025-10-18 15:32:18.446 ServerApp] Kernel interrupted: e1404771-63a0-436c-a7e5-d44e6258a1e8
Cancellation requested; stopping current tasks.
[I 2025-10-18 15:32:26.447 ServerApp] Kernel restarted: e1404771-63a0-436c-a7e5-d44e6258a1e8
[I 2025-10-18 15:32:26.477 ServerApp] Starting buffering for e1404771-63a0-436c-a7e5-d44e6258a1e8:666ea692-fe54-4de1-8104-1778e617dbd7
[I 2025-10-18 15:32:26.533 ServerApp] Connecting to kernel e1404771-63a0-436c-a7e5-d44e6258a1e8.
[I 2025-10-18 15:32:26.533 ServerApp] Restoring connection for e1404771-63a0-436c-a7e5-d44e6258a1e8:666ea692-fe54-4de1-8104-1778e617dbd7
[I 2025-10-18 15:32:37.917 ServerApp] Saving file at /PEFT-PT/peft-pt-2.ipynb
[I 2025-10-18 15:33:58.230 ServerApp] Saving file at /PEFT-PT/peft-pt-2.ipynb
[I 2025-10-18 15:35:58.684 ServerApp] Saving file at /PEFT-PT/peft-pt-2.ipynb
[I 2025-10-18 15:37:58.834 ServerApp] Saving file at /PEFT-PT/peft-pt-2.ipynb
[I 2025-10-18 15:55:12.976 ServerApp] 302 GET / (@192.168.241.22) 0.38ms
[I 2025-10-18 15:55:13.852 JupyterNotebookApp] 302 GET /tree? (@192.168.241.22) 0.61ms
[I 2025-10-18 15:55:21.500 ServerApp] 302 GET / (@192.168.241.22) 0.44ms
[I 2025-10-18 15:55:22.738 JupyterNotebookApp] 302 GET /tree? (@192.168.241.22) 0.56ms
[I 2025-10-18 15:57:45.676 ServerApp] User b1dcac89198a4c85b91132e2077a52e9 logged in.
[I 2025-10-18 15:57:45.677 ServerApp] 302 POST /login?next=%2Ftree%3F (b1dcac89198a4c85b91132e2077a52e9@192.168.241.22) 33.05ms
[I 2025-10-18 15:58:41.262 ServerApp] Connecting to kernel e1404771-63a0-436c-a7e5-d44e6258a1e8.
[I 2025-10-18 18:12:31.850 ServerApp] Kernel interrupted: e1404771-63a0-436c-a7e5-d44e6258a1e8
[I 2025-10-18 18:12:32.886 ServerApp] Kernel interrupted: e1404771-63a0-436c-a7e5-d44e6258a1e8
[I 2025-10-18 18:12:35.923 ServerApp] Kernel restarted: e1404771-63a0-436c-a7e5-d44e6258a1e8
[I 2025-10-18 18:12:35.954 ServerApp] Starting buffering for e1404771-63a0-436c-a7e5-d44e6258a1e8:666ea692-fe54-4de1-8104-1778e617dbd7
[I 2025-10-18 18:12:36.006 ServerApp] Connecting to kernel e1404771-63a0-436c-a7e5-d44e6258a1e8.
[I 2025-10-18 18:12:36.006 ServerApp] Restoring connection for e1404771-63a0-436c-a7e5-d44e6258a1e8:666ea692-fe54-4de1-8104-1778e617dbd7
[I 2025-10-18 18:13:59.190 ServerApp] Saving file at /PEFT-PT/peft-pt-2.ipynb
[I 2025-10-18 18:14:55.407 ServerApp] Saving file at /PEFT-PT/peft-pt-2.ipynb
[I 2025-10-18 18:14:58.359 ServerApp] Starting buffering for e1404771-63a0-436c-a7e5-d44e6258a1e8:666ea692-fe54-4de1-8104-1778e617dbd7
[I 2025-10-18 18:15:36.189 ServerApp] Connecting to kernel e1404771-63a0-436c-a7e5-d44e6258a1e8.
[I 2025-10-18 18:15:36.260 ServerApp] Starting buffering for e1404771-63a0-436c-a7e5-d44e6258a1e8:e2ea928e-98fb-441f-9477-5bd2bd4279aa
[I 2025-10-18 18:16:15.836 ServerApp] Kernel shutdown: e1404771-63a0-436c-a7e5-d44e6258a1e8
[I 2025-10-18 18:16:30.676 ServerApp] Copying 'PEFT-LoRA/dataset_instrucoes_juridico.jsonl' to '/PEFT-QLoRA-Axolotl'
[I 2025-10-18 18:18:06.389 ServerApp] Saving file at /PEFT-QLoRA-Axolotl/config_qlora.yml
[I 2025-10-18 18:20:12.626 ServerApp] Saving file at /PEFT-QLoRA-Axolotl/peft-qLoRA-Axolotl.ipynb
[I 2025-10-18 18:28:13.015 ServerApp] Saving file at /PEFT-QLoRA-Axolotl/peft-qLoRA-Axolotl.ipynb
[I 2025-10-18 18:30:13.123 ServerApp] Saving file at /PEFT-QLoRA-Axolotl/peft-qLoRA-Axolotl.ipynb
[I 2025-10-18 18:34:13.234 ServerApp] Saving file at /PEFT-QLoRA-Axolotl/peft-qLoRA-Axolotl.ipynb
[I 2025-10-18 18:42:58.511 ServerApp] Kernel started: d9b29c4a-5bbf-4787-88e1-d3d74613738d
[I 2025-10-18 18:42:58.890 ServerApp] Connecting to kernel d9b29c4a-5bbf-4787-88e1-d3d74613738d.
[I 2025-10-18 18:42:58.951 ServerApp] Starting buffering for d9b29c4a-5bbf-4787-88e1-d3d74613738d:6c6c6949-157d-43bb-aeed-3be628d95af6
[I 2025-10-18 18:42:58.985 ServerApp] Connecting to kernel d9b29c4a-5bbf-4787-88e1-d3d74613738d.
[I 2025-10-18 18:42:59.064 ServerApp] Connecting to kernel d9b29c4a-5bbf-4787-88e1-d3d74613738d.
[I 2025-10-18 18:43:00.149 ServerApp] Connecting to kernel d9b29c4a-5bbf-4787-88e1-d3d74613738d.
[I 2025-10-18 18:52:42.886 ServerApp] Kernel started: 1c95112a-9733-4ade-be8a-3134cf6205e7
[I 2025-10-18 18:52:42.888 ServerApp] Kernel shutdown: d9b29c4a-5bbf-4787-88e1-d3d74613738d
[I 2025-10-18 18:52:43.232 ServerApp] Connecting to kernel 1c95112a-9733-4ade-be8a-3134cf6205e7.
[I 2025-10-18 18:52:59.148 ServerApp] Saving file at /PEFT-PT/peft-pt-2.ipynb
[I 2025-10-18 18:55:00.002 ServerApp] Saving file at /PEFT-PT/peft-pt-2.ipynb
[I 2025-10-18 18:57:00.729 ServerApp] Saving file at /PEFT-PT/peft-pt-2.ipynb
[I 2025-10-18 19:01:01.857 ServerApp] Saving file at /PEFT-PT/peft-pt-2.ipynb
[I 2025-10-18 19:01:17.938 ServerApp] Connecting to kernel 1c95112a-9733-4ade-be8a-3134cf6205e7.
[W 2025-10-18 19:01:40.216 ServerApp] 400 GET /api/contents/PEFT-PT/modelo_juridico_prompt_tuning/prompt_adapter/adapter_model.safetensors?type=file&content=1&hash=1&format=text&contentProviderId=undefined&1760824900184 (192.168.241.22): /home/ricardo/fine-tuning-llm/PEFT-PT/modelo_juridico_prompt_tuning/prompt_adapter/adapter_model.safetensors is not UTF-8 encoded
[W 2025-10-18 19:01:40.216 ServerApp] wrote error: '/home/ricardo/fine-tuning-llm/PEFT-PT/modelo_juridico_prompt_tuning/prompt_adapter/adapter_model.safetensors is not UTF-8 encoded'
    Traceback (most recent call last):
      File "/usr/local/lib/python3.9/site-packages/jupyter_server/services/contents/fileio.py", line 562, in _read_file
        (bcontent.decode("utf8"), "text", bcontent)
    UnicodeDecodeError: 'utf-8' codec can't decode byte 0xd7 in position 121: invalid continuation byte
    
    The above exception was the direct cause of the following exception:
    
    Traceback (most recent call last):
      File "/usr/local/lib64/python3.9/site-packages/tornado/web.py", line 1848, in _execute
        result = await result
      File "/usr/local/lib/python3.9/site-packages/jupyter_server/auth/decorator.py", line 73, in inner
        return await out
      File "/usr/local/lib/python3.9/site-packages/jupyter_server/services/contents/handlers.py", line 156, in get
        model = await ensure_async(
      File "/usr/local/lib/python3.9/site-packages/jupyter_core/utils/__init__.py", line 197, in ensure_async
        result = await obj
      File "/usr/local/lib/python3.9/site-packages/jupyter_server/services/contents/filemanager.py", line 928, in get
        model = await self._file_model(
      File "/usr/local/lib/python3.9/site-packages/jupyter_server/services/contents/filemanager.py", line 837, in _file_model
        content, format, bytes_content = await self._read_file(os_path, format, raw=True)  # type: ignore[misc]
      File "/usr/local/lib/python3.9/site-packages/jupyter_server/services/contents/fileio.py", line 571, in _read_file
        raise HTTPError(
    tornado.web.HTTPError: HTTP 400: bad format (/home/ricardo/fine-tuning-llm/PEFT-PT/modelo_juridico_prompt_tuning/prompt_adapter/adapter_model.safetensors is not UTF-8 encoded)
[W 2025-10-18 19:01:40.217 ServerApp] 400 GET /api/contents/PEFT-PT/modelo_juridico_prompt_tuning/prompt_adapter/adapter_model.safetensors?type=file&content=1&hash=1&format=text&contentProviderId=undefined&1760824900184 (4e44c18e31e34792b64931a8b1f18873@192.168.241.22) 2.31ms referer=https://jupyter.pjc.mt.gov.br/tree/PEFT-PT/modelo_juridico_prompt_tuning/prompt_adapter
[I 2025-10-18 19:01:40.887 ServerApp] Connecting to kernel 1c95112a-9733-4ade-be8a-3134cf6205e7.
[W 2025-10-18 19:01:40.916 ServerApp] 400 GET /api/contents/PEFT-PT/modelo_juridico_prompt_tuning/prompt_adapter/adapter_model.safetensors?type=file&content=1&hash=1&format=text&contentProviderId=undefined&1760824900909 (192.168.241.22): /home/ricardo/fine-tuning-llm/PEFT-PT/modelo_juridico_prompt_tuning/prompt_adapter/adapter_model.safetensors is not UTF-8 encoded
[W 2025-10-18 19:01:40.916 ServerApp] wrote error: '/home/ricardo/fine-tuning-llm/PEFT-PT/modelo_juridico_prompt_tuning/prompt_adapter/adapter_model.safetensors is not UTF-8 encoded'
    Traceback (most recent call last):
      File "/usr/local/lib/python3.9/site-packages/jupyter_server/services/contents/fileio.py", line 562, in _read_file
        (bcontent.decode("utf8"), "text", bcontent)
    UnicodeDecodeError: 'utf-8' codec can't decode byte 0xd7 in position 121: invalid continuation byte
    
    The above exception was the direct cause of the following exception:
    
    Traceback (most recent call last):
      File "/usr/local/lib64/python3.9/site-packages/tornado/web.py", line 1848, in _execute
        result = await result
      File "/usr/local/lib/python3.9/site-packages/jupyter_server/auth/decorator.py", line 73, in inner
        return await out
      File "/usr/local/lib/python3.9/site-packages/jupyter_server/services/contents/handlers.py", line 156, in get
        model = await ensure_async(
      File "/usr/local/lib/python3.9/site-packages/jupyter_core/utils/__init__.py", line 197, in ensure_async
        result = await obj
      File "/usr/local/lib/python3.9/site-packages/jupyter_server/services/contents/filemanager.py", line 928, in get
        model = await self._file_model(
      File "/usr/local/lib/python3.9/site-packages/jupyter_server/services/contents/filemanager.py", line 837, in _file_model
        content, format, bytes_content = await self._read_file(os_path, format, raw=True)  # type: ignore[misc]
      File "/usr/local/lib/python3.9/site-packages/jupyter_server/services/contents/fileio.py", line 571, in _read_file
        raise HTTPError(
    tornado.web.HTTPError: HTTP 400: bad format (/home/ricardo/fine-tuning-llm/PEFT-PT/modelo_juridico_prompt_tuning/prompt_adapter/adapter_model.safetensors is not UTF-8 encoded)
[W 2025-10-18 19:01:40.916 ServerApp] 400 GET /api/contents/PEFT-PT/modelo_juridico_prompt_tuning/prompt_adapter/adapter_model.safetensors?type=file&content=1&hash=1&format=text&contentProviderId=undefined&1760824900909 (4e44c18e31e34792b64931a8b1f18873@192.168.241.22) 2.27ms referer=https://jupyter.pjc.mt.gov.br/edit/PEFT-PT/modelo_juridico_prompt_tuning/prompt_adapter/adapter_model.safetensors
[I 2025-10-18 19:03:02.038 ServerApp] Saving file at /PEFT-PT/peft-pt-2.ipynb
[I 2025-10-18 19:05:02.488 ServerApp] Saving file at /PEFT-PT/peft-pt-2.ipynb
[I 2025-10-18 19:07:02.646 ServerApp] Saving file at /PEFT-PT/peft-pt-2.ipynb
[I 2025-10-18 19:09:02.802 ServerApp] Saving file at /PEFT-PT/peft-pt-2.ipynb
[I 2025-10-18 19:11:02.953 ServerApp] Saving file at /PEFT-PT/peft-pt-2.ipynb
[I 2025-10-18 19:13:01.076 ServerApp] Saving file at /PEFT-PT/peft-pt-2.ipynb
[I 2025-10-18 19:19:42.381 ServerApp] Kernel interrupted: 1c95112a-9733-4ade-be8a-3134cf6205e7
[I 2025-10-18 19:19:43.204 ServerApp] Kernel interrupted: 1c95112a-9733-4ade-be8a-3134cf6205e7
[I 2025-10-18 19:19:44.933 ServerApp] Starting buffering for 1c95112a-9733-4ade-be8a-3134cf6205e7:ed14e262-7f49-461c-b9c3-4390c42e074e
[I 2025-10-18 19:20:21.272 ServerApp] Saving file at /PEFT-QLoRA-Axolotl/peft-qLoRA-Axolotl.ipynb
[I 2025-10-18 19:22:21.373 ServerApp] Saving file at /PEFT-QLoRA-Axolotl/peft-qLoRA-Axolotl.ipynb
[I 2025-10-18 19:34:00.080 ServerApp] Connecting to kernel 1c95112a-9733-4ade-be8a-3134cf6205e7.
[I 2025-10-18 19:34:00.143 ServerApp] Starting buffering for 1c95112a-9733-4ade-be8a-3134cf6205e7:329bf5bb-1fd9-404d-85fb-1613a711af7e
[I 2025-10-18 19:34:23.283 ServerApp] Saving file at /PEFT-QLoRA-Axolotl/config_qlora.yml
[I 2025-10-18 19:40:22.154 ServerApp] Saving file at /PEFT-QLoRA-Axolotl/peft-qLoRA-Axolotl.ipynb
[I 2025-10-18 19:42:24.687 ServerApp] Saving file at /PEFT-QLoRA-Axolotl/config_qlora.yml
[I 2025-10-18 19:44:16.940 ServerApp] Saving file at /PEFT-QLoRA-Axolotl/config_qlora.yml
[I 2025-10-18 19:44:20.008 ServerApp] Saving file at /PEFT-QLoRA-Axolotl/config_qlora.yml
[I 2025-10-18 19:45:22.564 ServerApp] Connecting to kernel 1c95112a-9733-4ade-be8a-3134cf6205e7.
[I 2025-10-18 19:45:22.645 ServerApp] Starting buffering for 1c95112a-9733-4ade-be8a-3134cf6205e7:da25f066-6cd3-4ebb-877f-69578c7be4ed
[I 2025-10-18 19:47:54.152 ServerApp] Connecting to kernel 1c95112a-9733-4ade-be8a-3134cf6205e7.
[I 2025-10-18 19:47:54.207 ServerApp] Starting buffering for 1c95112a-9733-4ade-be8a-3134cf6205e7:f89c960c-18aa-4beb-bcc6-f7d6ea979593
[I 2025-10-18 19:48:29.185 ServerApp] Connecting to kernel 1c95112a-9733-4ade-be8a-3134cf6205e7.
[I 2025-10-18 19:48:29.241 ServerApp] Starting buffering for 1c95112a-9733-4ade-be8a-3134cf6205e7:fcafbb60-0853-4521-96ba-be60a87a512c
[I 2025-10-18 19:52:17.418 ServerApp] Saving file at /PEFT-QLoRA-Axolotl/config_qlora.yml
[I 2025-10-18 19:52:30.223 ServerApp] Saving file at /PEFT-QLoRA-Axolotl/config_qlora.yml
[I 2025-10-18 19:54:30.323 ServerApp] Saving file at /PEFT-QLoRA-Axolotl/config_qlora.yml
[I 2025-10-18 19:58:30.894 ServerApp] Saving file at /PEFT-QLoRA-Axolotl/config_qlora.yml
[I 2025-10-18 19:58:57.579 ServerApp] Saving file at /PEFT-QLoRA-Axolotl/config_qlora.yml
[I 2025-10-18 20:02:58.358 ServerApp] Saving file at /PEFT-QLoRA-Axolotl/config_qlora.yml
[I 2025-10-18 20:04:28.128 ServerApp] Saving file at /PEFT-QLoRA-Axolotl/peft-qLoRA-Axolotl.ipynb
[I 2025-10-18 20:04:37.807 ServerApp] Connecting to kernel 1c95112a-9733-4ade-be8a-3134cf6205e7.
[I 2025-10-18 20:04:37.998 ServerApp] Starting buffering for 1c95112a-9733-4ade-be8a-3134cf6205e7:76a93f8b-d5b4-4e75-9dd9-a65bc08615d5
[I 2025-10-18 20:04:45.802 ServerApp] Kernel started: 2c4bcee4-c3d5-4f04-8b89-344d186ba833
[I 2025-10-18 20:04:46.229 ServerApp] Connecting to kernel 2c4bcee4-c3d5-4f04-8b89-344d186ba833.
[I 2025-10-18 20:04:46.284 ServerApp] Starting buffering for 2c4bcee4-c3d5-4f04-8b89-344d186ba833:046b6ed4-90ab-45d6-8f98-788a163312ad
[I 2025-10-18 20:04:46.307 ServerApp] Connecting to kernel 2c4bcee4-c3d5-4f04-8b89-344d186ba833.
[I 2025-10-18 20:04:46.383 ServerApp] Connecting to kernel 2c4bcee4-c3d5-4f04-8b89-344d186ba833.
[I 2025-10-18 20:05:15.661 ServerApp] Connecting to kernel 2c4bcee4-c3d5-4f04-8b89-344d186ba833.
[I 2025-10-18 20:05:33.823 ServerApp] Connecting to kernel 2c4bcee4-c3d5-4f04-8b89-344d186ba833.
[I 2025-10-18 20:06:03.061 ServerApp] Saving file at /PEFT-QLoRA-Axolotl/config_qlora.yml
[I 2025-10-18 20:06:38.842 ServerApp] Saving file at /PEFT-QLoRA-Axolotl/peft-qLoRA-Axolotl.ipynb
[I 2025-10-19 00:50:36.476 ServerApp] Connecting to kernel 1c95112a-9733-4ade-be8a-3134cf6205e7.
[I 2025-10-19 00:50:36.551 ServerApp] Connecting to kernel 2c4bcee4-c3d5-4f04-8b89-344d186ba833.
[I 2025-10-19 00:50:36.613 ServerApp] Starting buffering for 1c95112a-9733-4ade-be8a-3134cf6205e7:212cbe2c-ae13-4205-b76e-261aaaf66cc1
[I 2025-10-19 00:53:54.356 ServerApp] Saving file at /PEFT-QLoRA-Axolotl/config_qlora.yml
[I 2025-10-19 00:58:02.693 ServerApp] Connecting to kernel 1c95112a-9733-4ade-be8a-3134cf6205e7.
[I 2025-10-19 00:58:02.770 ServerApp] Connecting to kernel 2c4bcee4-c3d5-4f04-8b89-344d186ba833.
[I 2025-10-19 00:58:02.780 ServerApp] Starting buffering for 1c95112a-9733-4ade-be8a-3134cf6205e7:2482c408-0b31-4472-be0e-ff0c6d34a092
[I 2025-10-19 00:58:10.720 ServerApp] Connecting to kernel 1c95112a-9733-4ade-be8a-3134cf6205e7.
[I 2025-10-19 00:58:10.776 ServerApp] Starting buffering for 1c95112a-9733-4ade-be8a-3134cf6205e7:6bee57a5-05da-4b34-8de2-02faf3203037
[I 2025-10-19 00:58:10.803 ServerApp] Connecting to kernel 2c4bcee4-c3d5-4f04-8b89-344d186ba833.
[W 2025-10-19 00:58:14.410 ServerApp] 400 GET /api/contents/PEFT-QLoRA-Axolotl/last_run_prepared/d732893e332a5960b3b9fb2d38878e31/data-00003-of-00004.arrow?type=file&content=1&hash=1&format=text&contentProviderId=undefined&1760846294370 (192.168.241.22): /home/ricardo/fine-tuning-llm/PEFT-QLoRA-Axolotl/last_run_prepared/d732893e332a5960b3b9fb2d38878e31/data-00003-of-00004.arrow is not UTF-8 encoded
[W 2025-10-19 00:58:14.410 ServerApp] wrote error: '/home/ricardo/fine-tuning-llm/PEFT-QLoRA-Axolotl/last_run_prepared/d732893e332a5960b3b9fb2d38878e31/data-00003-of-00004.arrow is not UTF-8 encoded'
    Traceback (most recent call last):
      File "/usr/local/lib/python3.9/site-packages/jupyter_server/services/contents/fileio.py", line 562, in _read_file
        (bcontent.decode("utf8"), "text", bcontent)
    UnicodeDecodeError: 'utf-8' codec can't decode byte 0xff in position 0: invalid start byte
    
    The above exception was the direct cause of the following exception:
    
    Traceback (most recent call last):
      File "/usr/local/lib64/python3.9/site-packages/tornado/web.py", line 1848, in _execute
        result = await result
      File "/usr/local/lib/python3.9/site-packages/jupyter_server/auth/decorator.py", line 73, in inner
        return await out
      File "/usr/local/lib/python3.9/site-packages/jupyter_server/services/contents/handlers.py", line 156, in get
        model = await ensure_async(
      File "/usr/local/lib/python3.9/site-packages/jupyter_core/utils/__init__.py", line 197, in ensure_async
        result = await obj
      File "/usr/local/lib/python3.9/site-packages/jupyter_server/services/contents/filemanager.py", line 928, in get
        model = await self._file_model(
      File "/usr/local/lib/python3.9/site-packages/jupyter_server/services/contents/filemanager.py", line 837, in _file_model
        content, format, bytes_content = await self._read_file(os_path, format, raw=True)  # type: ignore[misc]
      File "/usr/local/lib/python3.9/site-packages/jupyter_server/services/contents/fileio.py", line 571, in _read_file
        raise HTTPError(
    tornado.web.HTTPError: HTTP 400: bad format (/home/ricardo/fine-tuning-llm/PEFT-QLoRA-Axolotl/last_run_prepared/d732893e332a5960b3b9fb2d38878e31/data-00003-of-00004.arrow is not UTF-8 encoded)
[W 2025-10-19 00:58:14.411 ServerApp] 400 GET /api/contents/PEFT-QLoRA-Axolotl/last_run_prepared/d732893e332a5960b3b9fb2d38878e31/data-00003-of-00004.arrow?type=file&content=1&hash=1&format=text&contentProviderId=undefined&1760846294370 (4e44c18e31e34792b64931a8b1f18873@192.168.241.22) 3.79ms referer=https://jupyter.pjc.mt.gov.br/tree/PEFT-QLoRA-Axolotl/last_run_prepared/d732893e332a5960b3b9fb2d38878e31
[I 2025-10-19 00:58:15.116 ServerApp] Connecting to kernel 1c95112a-9733-4ade-be8a-3134cf6205e7.
[W 2025-10-19 00:58:15.145 ServerApp] 400 GET /api/contents/PEFT-QLoRA-Axolotl/last_run_prepared/d732893e332a5960b3b9fb2d38878e31/data-00003-of-00004.arrow?type=file&content=1&hash=1&format=text&contentProviderId=undefined&1760846295128 (192.168.241.22): /home/ricardo/fine-tuning-llm/PEFT-QLoRA-Axolotl/last_run_prepared/d732893e332a5960b3b9fb2d38878e31/data-00003-of-00004.arrow is not UTF-8 encoded
[W 2025-10-19 00:58:15.145 ServerApp] wrote error: '/home/ricardo/fine-tuning-llm/PEFT-QLoRA-Axolotl/last_run_prepared/d732893e332a5960b3b9fb2d38878e31/data-00003-of-00004.arrow is not UTF-8 encoded'
    Traceback (most recent call last):
      File "/usr/local/lib/python3.9/site-packages/jupyter_server/services/contents/fileio.py", line 562, in _read_file
        (bcontent.decode("utf8"), "text", bcontent)
    UnicodeDecodeError: 'utf-8' codec can't decode byte 0xff in position 0: invalid start byte
    
    The above exception was the direct cause of the following exception:
    
    Traceback (most recent call last):
      File "/usr/local/lib64/python3.9/site-packages/tornado/web.py", line 1848, in _execute
        result = await result
      File "/usr/local/lib/python3.9/site-packages/jupyter_server/auth/decorator.py", line 73, in inner
        return await out
      File "/usr/local/lib/python3.9/site-packages/jupyter_server/services/contents/handlers.py", line 156, in get
        model = await ensure_async(
      File "/usr/local/lib/python3.9/site-packages/jupyter_core/utils/__init__.py", line 197, in ensure_async
        result = await obj
      File "/usr/local/lib/python3.9/site-packages/jupyter_server/services/contents/filemanager.py", line 928, in get
        model = await self._file_model(
      File "/usr/local/lib/python3.9/site-packages/jupyter_server/services/contents/filemanager.py", line 837, in _file_model
        content, format, bytes_content = await self._read_file(os_path, format, raw=True)  # type: ignore[misc]
      File "/usr/local/lib/python3.9/site-packages/jupyter_server/services/contents/fileio.py", line 571, in _read_file
        raise HTTPError(
    tornado.web.HTTPError: HTTP 400: bad format (/home/ricardo/fine-tuning-llm/PEFT-QLoRA-Axolotl/last_run_prepared/d732893e332a5960b3b9fb2d38878e31/data-00003-of-00004.arrow is not UTF-8 encoded)
[W 2025-10-19 00:58:15.146 ServerApp] 400 GET /api/contents/PEFT-QLoRA-Axolotl/last_run_prepared/d732893e332a5960b3b9fb2d38878e31/data-00003-of-00004.arrow?type=file&content=1&hash=1&format=text&contentProviderId=undefined&1760846295128 (4e44c18e31e34792b64931a8b1f18873@192.168.241.22) 2.71ms referer=https://jupyter.pjc.mt.gov.br/edit/PEFT-QLoRA-Axolotl/last_run_prepared/d732893e332a5960b3b9fb2d38878e31/data-00003-of-00004.arrow
[I 2025-10-19 00:58:15.194 ServerApp] Connecting to kernel 2c4bcee4-c3d5-4f04-8b89-344d186ba833.
[I 2025-10-19 00:58:15.199 ServerApp] Starting buffering for 1c95112a-9733-4ade-be8a-3134cf6205e7:019ea4ab-b1a8-4a04-9d02-e0aaff4c921a
[I 2025-10-19 00:58:43.497 ServerApp] Connecting to kernel 1c95112a-9733-4ade-be8a-3134cf6205e7.
[I 2025-10-19 00:58:43.610 ServerApp] Connecting to kernel 2c4bcee4-c3d5-4f04-8b89-344d186ba833.
[I 2025-10-19 00:58:43.636 ServerApp] Starting buffering for 1c95112a-9733-4ade-be8a-3134cf6205e7:8d0e9288-7b0c-4aed-a828-698181a8c96c
[I 2025-10-19 00:59:08.044 ServerApp] Connecting to kernel 1c95112a-9733-4ade-be8a-3134cf6205e7.
[I 2025-10-19 00:59:08.117 ServerApp] Connecting to kernel 2c4bcee4-c3d5-4f04-8b89-344d186ba833.
[I 2025-10-19 00:59:08.151 ServerApp] Starting buffering for 1c95112a-9733-4ade-be8a-3134cf6205e7:5416c745-1bfb-4b94-b103-2bc3f7baf743
[I 2025-10-19 01:00:05.852 ServerApp] Saving file at /PEFT-QLoRA-Axolotl/peft-qLoRA-Axolotl.ipynb
[I 2025-10-19 01:00:13.310 ServerApp] Connecting to kernel 1c95112a-9733-4ade-be8a-3134cf6205e7.
[I 2025-10-19 01:00:13.425 ServerApp] Connecting to kernel 2c4bcee4-c3d5-4f04-8b89-344d186ba833.
[I 2025-10-19 01:00:13.480 ServerApp] Starting buffering for 1c95112a-9733-4ade-be8a-3134cf6205e7:ee10fa93-fc92-4e43-a564-9015826325da
[I 2025-10-19 01:00:13.639 ServerApp] Kernel started: 6320e992-0c15-4cb9-89df-9117283f988b
[I 2025-10-19 01:00:14.095 ServerApp] Connecting to kernel 6320e992-0c15-4cb9-89df-9117283f988b.
[I 2025-10-19 01:00:14.143 ServerApp] Starting buffering for 6320e992-0c15-4cb9-89df-9117283f988b:c30913b1-1fd0-4369-b172-0e9ab7cc30d8
[I 2025-10-19 01:00:14.166 ServerApp] Connecting to kernel 6320e992-0c15-4cb9-89df-9117283f988b.
[I 2025-10-19 01:00:14.257 ServerApp] Connecting to kernel 6320e992-0c15-4cb9-89df-9117283f988b.
[I 2025-10-19 01:00:25.132 ServerApp] Starting buffering for 6320e992-0c15-4cb9-89df-9117283f988b:68cca222-cb11-4fa5-97aa-db6ee805a28c
[I 2025-10-19 01:00:30.859 ServerApp] Connecting to kernel 6320e992-0c15-4cb9-89df-9117283f988b.
[I 2025-10-19 01:00:30.920 ServerApp] Starting buffering for 6320e992-0c15-4cb9-89df-9117283f988b:3a6d2d1d-5bc6-45f6-b4ed-d9284f6c78b2
[I 2025-10-19 01:01:03.957 ServerApp] Connecting to kernel 6320e992-0c15-4cb9-89df-9117283f988b.
[I 2025-10-19 01:01:04.010 ServerApp] Starting buffering for 6320e992-0c15-4cb9-89df-9117283f988b:63a58285-5bfd-489e-a476-efef0198485e
[I 2025-10-19 01:02:05.956 ServerApp] Saving file at /PEFT-QLoRA-Axolotl/peft-qLoRA-Axolotl.ipynb
[I 2025-10-19 01:04:06.063 ServerApp] Saving file at /PEFT-QLoRA-Axolotl/peft-qLoRA-Axolotl.ipynb
[I 2025-10-19 01:06:06.208 ServerApp] Saving file at /PEFT-QLoRA-Axolotl/peft-qLoRA-Axolotl.ipynb
[I 2025-10-19 01:06:34.447 ServerApp] Connecting to kernel 1c95112a-9733-4ade-be8a-3134cf6205e7.
[I 2025-10-19 01:06:34.563 ServerApp] Connecting to kernel 2c4bcee4-c3d5-4f04-8b89-344d186ba833.
[I 2025-10-19 01:06:34.610 ServerApp] Starting buffering for 1c95112a-9733-4ade-be8a-3134cf6205e7:990e9f3e-efd6-49a4-9830-49996d395deb
[I 2025-10-19 01:06:34.650 ServerApp] Connecting to kernel 6320e992-0c15-4cb9-89df-9117283f988b.
[I 2025-10-19 01:06:34.801 ServerApp] Starting buffering for 6320e992-0c15-4cb9-89df-9117283f988b:5c841c8f-abcd-4dc5-8601-f36d26c0fa41
[I 2025-10-19 01:06:34.871 ServerApp] Connecting to kernel 6320e992-0c15-4cb9-89df-9117283f988b.
[I 2025-10-19 01:08:06.316 ServerApp] Saving file at /PEFT-QLoRA-Axolotl/peft-qLoRA-Axolotl.ipynb
[I 2025-10-19 01:10:06.452 ServerApp] Saving file at /PEFT-QLoRA-Axolotl/peft-qLoRA-Axolotl.ipynb
[I 2025-10-19 01:14:06.559 ServerApp] Saving file at /PEFT-QLoRA-Axolotl/peft-qLoRA-Axolotl.ipynb
[I 2025-10-19 01:22:06.688 ServerApp] Saving file at /PEFT-QLoRA-Axolotl/peft-qLoRA-Axolotl.ipynb
[I 2025-10-19 01:24:05.152 ServerApp] Saving file at /PEFT-QLoRA-Axolotl/peft-qLoRA-Axolotl.ipynb
[I 2025-10-19 01:34:05.292 ServerApp] Saving file at /PEFT-QLoRA-Axolotl/peft-qLoRA-Axolotl.ipynb
[I 2025-10-19 01:42:35.978 ServerApp] Connecting to kernel 6320e992-0c15-4cb9-89df-9117283f988b.
[I 2025-10-19 01:43:37.662 ServerApp] Starting buffering for 6320e992-0c15-4cb9-89df-9117283f988b:e4246b76-0d16-4475-a64c-1d831a307b41
[I 2025-10-19 01:43:56.375 ServerApp] Starting buffering for 2c4bcee4-c3d5-4f04-8b89-344d186ba833:23fe998c-e1ae-4957-b260-7909dd039614
[I 2025-10-19 03:12:02.158 ServerApp] Kernel shutdown: 1c95112a-9733-4ade-be8a-3134cf6205e7
[I 2025-10-19 03:12:02.159 ServerApp] Kernel shutdown: 2c4bcee4-c3d5-4f04-8b89-344d186ba833
[I 2025-10-19 03:12:02.207 ServerApp] Kernel shutdown: 6320e992-0c15-4cb9-89df-9117283f988b
[I 2025-10-19 03:12:29.036 ServerApp] Creating new directory in 
[I 2025-10-19 03:12:46.432 ServerApp] Creating new notebook in /FT-DPO
[I 2025-10-19 03:13:58.314 ServerApp] Creating new file in /FT-DPO
[I 2025-10-19 03:14:18.071 ServerApp] Saving file at /FT-DPO/dataset_preferencias_juridico.jsonl.txt
[I 2025-10-19 03:15:15.623 ServerApp] Kernel started: 26c6fae7-5f61-449e-a296-61bc9b61f0b6
[I 2025-10-19 03:15:16.034 ServerApp] Connecting to kernel 26c6fae7-5f61-449e-a296-61bc9b61f0b6.
[I 2025-10-19 03:15:16.084 ServerApp] Starting buffering for 26c6fae7-5f61-449e-a296-61bc9b61f0b6:e17fa86f-212b-4bd0-8911-e533c5d07871
[I 2025-10-19 03:15:16.110 ServerApp] Connecting to kernel 26c6fae7-5f61-449e-a296-61bc9b61f0b6.
[I 2025-10-19 03:15:16.181 ServerApp] Connecting to kernel 26c6fae7-5f61-449e-a296-61bc9b61f0b6.
[I 2025-10-19 03:15:44.504 ServerApp] Saving file at /FT-DPO/ft_dpo.ipynb
[I 2025-10-19 03:17:44.642 ServerApp] Saving file at /FT-DPO/ft_dpo.ipynb
[I 2025-10-19 03:19:44.758 ServerApp] Saving file at /FT-DPO/ft_dpo.ipynb
[I 2025-10-19 03:21:44.899 ServerApp] Saving file at /FT-DPO/ft_dpo.ipynb
[I 2025-10-19 03:22:10.394 ServerApp] Saving file at /FT-DPO/ft_dpo.ipynb
[I 2025-10-19 21:10:46.755 ServerApp] Connecting to kernel 26c6fae7-5f61-449e-a296-61bc9b61f0b6.
[I 2025-10-19 21:10:47.105 ServerApp] Kernel started: 593b32fc-eb7a-4a49-80e1-dd7c3cd78fef
[I 2025-10-19 21:10:47.517 ServerApp] Connecting to kernel 593b32fc-eb7a-4a49-80e1-dd7c3cd78fef.
[I 2025-10-19 21:10:47.545 ServerApp] Starting buffering for 593b32fc-eb7a-4a49-80e1-dd7c3cd78fef:b350c1ef-7127-4e5d-b6c2-727b5621a25c
[I 2025-10-19 21:10:49.215 ServerApp] Connecting to kernel 26c6fae7-5f61-449e-a296-61bc9b61f0b6.
[I 2025-10-19 21:10:49.303 ServerApp] Connecting to kernel 593b32fc-eb7a-4a49-80e1-dd7c3cd78fef.
[I 2025-10-19 21:10:49.351 ServerApp] Starting buffering for 593b32fc-eb7a-4a49-80e1-dd7c3cd78fef:fefe105a-40c3-4358-a5ec-095b2f72ccdc
